Workbook

Sheet 1
A1: NOM | B1: Nucleide | C1: E kev | D1: Canaux | E1: %emis | F1: Rendement | G1: temps | H1: poids | I1: bdf | J1: eff | K1: pic1 | L1: bdfg | M1: bdfd | O1: pic net | Q1: cpm | S1: dpm/g | V1: Bq/k | X1: Data Certif
A2: RGU | B2: 210Pb | C2: 46.5 | D2: 9 | E2: 0.04 | F2: 0.535 | G2: =82138/60 -> 1368.9667 | H2: =2.96-1.81 -> 1.15 | I2: 0 | J2: 0.0214 | K2: 2728 | L2: 242 | M2: 260 | N2: =K2-(L2+M2)/2 -> 2477 | O2: ± | P2: =SQRT((K2+(L2+M2)/2)) -> 54.580216 | Q2: =N2/G2 -> 1.8093939 | R2: =(Q2/H2/J2) -> 73.522712 | S2: ± | T2: =P2/N2*R2 -> 1.6200588 | U2: =R2/60*1000 -> 1225.3785 | V2: ± | W2: =T2/R2*U2 -> 27.000979 | X2: 4940
A3: IAEA447 | B3: 241Am | C3: 59.5 | D3: 8 | E3: 0.363 | F3: 0.71625344 | G3: =G2 -> 1368.9667 | H3: =H2 -> 1.15 | I3: 0 | J3: 0.26 | K3: 243 | L3: 181 | M3: 182 | N3: =K3-(L3+M3)/2 -> 61.5 | O3: ± | P3: =SQRT((K3+(L3+M3)/2)) -> 20.603398 | Q3: =N3/G3 -> 0.044924396 | R3: =Q3/H3/J3 -> 0.15024881 | S3: ± | T3: =P3/N3*R3 -> 0.050335546 | U3: =R3/60*1000 -> 2.5041469 | V3: ± | W3: =T3/R3*U3 -> 0.83892577 | X3: 2.15
A4: RGU1 | B4: 214Bi | C4: 295 | D4: 11 | E4: 0.192 | F4: 0.421875 | G4: =G2 -> 1368.9667 | H4: =H2 -> 1.15 | J4: 0.081 | K4: 1470 | L4: 66 | M4: 57 | N4: =K4-(L4+M4)/2 -> 1408.5 | O4: ± | P4: =SQRT((K4+(L4+M4)/2)) -> 39.134384 | Q4: =N4/G4 -> 1.0288782 | R4: =(Q4/H4/J4) -> 11.045392 | S4: ± | T4: =P4/N4*R4 -> 0.30689002 | U4: =R4/60*1000 -> 184.08986 | V4: ± | W4: =T4/R4*U4 -> 5.1148337 | X4: 4940
A5: RGU1 | B5: 214Bi | C5: 352 | D5: 12 | E5: 0.371 | F5: 0.36927224 | G5: =G2 -> 1368.9667 | H5: =H2 -> 1.15 | I5: 0.002 | J5: 0.137 | K5: 2438 | L5: 78 | M5: 66 | N5: =K5-(L5+M5)/2 -> 2366 | O5: ± | P5: =SQRT((K5+(L5+M5)/2)) -> 50.0999 | Q5: =N5/G5 -> 1.7283109 | R5: =(Q5/H5/J5) -> 10.96992 | S5: ± | T5: =P5/N5*R5 -> 0.23228736 | U5: =R5/60*1000 -> 182.832 | V5: ± | W5: =T5/R5*U5 -> 3.871456 | X5: 4940
A6: RGU1 | B6: 214Bi | C6: 609 | D6: 16 | E6: 0.461 | F6: 0.09978308 | G6: =G2 -> 1368.9667 | H6: =H2 -> 1.15 | I6: 0.002 | J6: 0.046 | K6: 839 | L6: 47 | M6: 42 | N6: =K6-(L6+M6)/2 -> 794.5 | O6: ± | P6: =SQRT((K6+(L6+M6)/2)) -> 29.723728 | Q6: =N6/G6 -> 0.58036475 | R6: =(Q6/H6/J6) -> 10.970978 | S6: ± | T6: =P6/N6*R6 -> 0.41044477 | U6: =R6/60*1000 -> 182.84964 | V6: ± | W6: =T6/R6*U6 -> 6.8407462 | X6: 4940
A7: IAEA447 | B7: 137Cs | C7: 661 | D7: 20 | E7: 0.8462 | F7: 0.29189317 | G7: =G2 -> 1368.9667 | H7: =H2 -> 1.15 | I7: 0.001 | J7: 0.247 | K7: 2579 | L7: 55 | M7: 33 | N7: =K7-(L7+M7)/2 -> 2535 | O7: ± | P7: =SQRT((K7+(L7+M7)/2)) -> 51.215232 | Q7: =N7/G7 -> 1.8517617 | R7: =Q7/H7/J7 -> 6.5191398 | S7: ± | T7: =P7/N7*R7 -> 0.13170779 | U7: =R7/60*1000 -> 108.65233 | V7: ± | W7: =T7/R7*U7 -> 2.1951299 | X7: 335
A8: RGU | B8: 40K | C8: 1460 | D8: 20 | E8: 0.107 | F8: 0.14485981 | G8: =G2 -> 1368.9667 | H8: =H2 -> 1.15 | I8: 0.004 | J8: 0.0155 | K8: 1128 | L8: 29 | M8: 16 | N8: =K8-(L8+M8)/2 -> 1105.5 | O8: ± | P8: =SQRT((K8+(L8+M8)/2)) -> 33.919021 | Q8: =N8/G8 -> 0.8075434 | R8: =Q8/H8/J8 -> 45.303978 | S8: ± | T8: =P8/N8*R8 -> 1.3900195 | U8: =R8/60*1000 -> 755.0663 | V8: ± | W8: =T8/R8*U8 -> 23.166992 | X8: 550
A9: RGTh | B9: 212Pb | C9: 238 | D9: 11 | E9: 0.431 | G9: =G3 -> 1368.9667 | H9: =H2 -> 1.15 | J9: 0.19 | K9: 1676 | L9: 110 | M9: 89 | N9: =K9-(L9+M9)/2 -> 1576.5 | P9: =SQRT((K9+(L9+M9)/2)) -> 42.136682 | Q9: =N9/G9 -> 1.1515985 | R9: =Q9/H9/J9 -> 5.2704738 | S9: ± | T9: =P9/N9*R9 -> 0.14086919 | U9: =R9/60*1000 -> 87.84123 | V9: ± | W9: =T9/R9*U9 -> 2.3478199
A10: RGTh | B10: 208Tl | C10: 583 | D10: 13 | G10: =G4 -> 1368.9667 | H10: =H2 -> 1.15 | J10: 0.025 | K10: 249 | L10: 43 | M10: 57 | N10: =K10-(L10+M10)/2 -> 199 | P10: =SQRT((K10+(L10+M10)/2)) -> 17.291616 | Q10: =N10/G10 -> 0.14536512 | R10: =Q10/H10/J10 -> 5.056178 | S10: ± | T10: =P10/N10*R10 -> 0.43934417 | U10: =R10/60*1000 -> 84.269633 | V10: ± | W10: =T10/R10*U10 -> 7.3224029
A11: RGTh | B11: 228Ac | C11: 338 | D11: 16 | E11: 0.12 | G11: =G3 -> 1368.9667 | H11: =H2 -> 1.15 | J11: 0.031 | K11: 301 | L11: 69 | M11: 53 | N11: =K11-(L11+M11)/2 -> 240 | P11: =SQRT((K11+(L11+M11)/2)) -> 19.026298 | Q11: =N11/G11 -> 0.17531471 | R11: =Q11/H11/J11 -> 4.9176638 | S11: ± | T11: =P11/N11*R11 -> 0.38985389 | U11: =R11/60*1000 -> 81.961063 | V11: ± | W11: =T11/R11*U11 -> 6.4975649
A12: RGTh | B12: 228Ac | C12: 911 | D12: 20 | E12: 0.29 | G12: =G2 -> 1368.9667 | H12: =H2 -> 1.15 | J12: 0.03 | K12: 290 | L12: 39 | M12: 38 | N12: =K12-(L12+M12)/2 -> 251.5 | P12: =SQRT((K12+(L12+M12)/2)) -> 18.124569 | Q12: =N12/G12 -> 0.18371521 | R12: =Q12/H12/J12 -> 5.3250786 | S12: ± | T12: =P12/N12*R12 -> 0.38375648 | U12: =R12/60*1000 -> 88.75131 | V12: ± | W12: =T12/R12*U12 -> 6.3959413
A13: RGTh | B13: 228Ac | C13: 968 | D13: 14 | E13: 0.18 | G13: =G3 -> 1368.9667 | H13: =H2 -> 1.15 | J13: 0.018 | K13: 179 | L13: 30 | M13: 30 | N13: =K13-(L13+M13)/2 -> 149 | P13: =SQRT((K13+(L13+M13)/2)) -> 14.456832 | Q13: =N13/G13 -> 0.10884122 | R13: =Q13/H13/J13 -> 5.2580299 | S13: ± | T13: =P13/N13*R13 -> 0.51016414 | U13: =R13/60*1000 -> 87.633831 | V13: ± | W13: =T13/R13*U13 -> 8.5027356
B14: Somme 226Ra | G14: =G2 -> 1368.9667 | H14: =H2 -> 1.15 | I14: 0.005 | J14: =J4+J5+J6 -> 0.264 | K14: =K4+K5+K6 -> 4747 | L14: =L4+L5+L6 -> 191 | M14: =M4+M5+M6 -> 165 | N14: =N4+N5+N6 -> 4569 | O14: ± | P14: =SQRT((K14+(L14+M14)/2)) -> 70.178344 | Q14: =N14/G14 -> 3.3375539 | R14: =(Q14/H14/J14) -> 10.99326 | S14: ± | T14: =P14/N14*R14 -> 0.16885288 | U14: =R14/60*1000 -> 183.22101 | V14: ± | W14: =T14/R14*U14 -> 2.8142147
B15: Somme 228Th | G15: =G14 -> 1368.9667 | H15: =H14 -> 1.15 | I15: 0.005 | J15: =J9+J10 -> 0.215 | K15: =K9+K10 -> 1925 | L15: =L9+L10 -> 153 | M15: =M9+M10 -> 146 | N15: =N9+N10 -> 1775.5 | O15: ± | P15: =SQRT((K15+(L15+M15)/2)) -> 45.546679 | Q15: =N15/G15 -> 1.2969636 | R15: =(Q15/H15/J15) -> 5.2455557 | S15: ± | T15: =P15/N15*R15 -> 0.13456358 | U15: =R15/60*1000 -> 87.425928 | V15: ± | W15: =T15/R15*U15 -> 2.2427264 | X15: 3225
B16: Somme 228Ra | G16: =G10 -> 1368.9667 | H16: =H10 -> 1.15 | I16: 0.005 | J16: =J11+J12+J13 -> 0.079 | K16: =K11+K12+K13 -> 770 | L16: =L11+L12+L13 -> 138 | M16: =M11+M12+M13 -> 121 | N16: =N11+N12+N13 -> 640.5 | O16: ± | P16: =SQRT((K16+(L16+M16)/2)) -> 29.991666 | Q16: =N16/G16 -> 0.46787114 | R16: =(Q16/H16/J16) -> 5.14993 | S16: ± | T16: =P16/N16*R16 -> 0.24114751 | U16: =R16/60*1000 -> 85.832167 | V16: ± | W16: =T16/R16*U16 -> 4.0191251 | X16: 3225
A18: NOI_1 | B18: 82 138,000
A20: Isotope | B20: Energie(Kev) | C20: Somme pic | D20: Somme bkg gauche | E20: Somme bkg droit | F20: Somme-bkg | G20: Sigma
A21: 210Pb | B21: 46.4991 | C21: 2 728 | D21: 242 | E21: 260 | F21: 2 502 | G21: 52.23
A22: 241Am | B22: 59.9337 | C22: 243 | D22: 181 | E22: 182 | F22: 81 | G22: 15.59
A23: 214Pb | B23: 295.178 | C23: 1 470 | D23: 66 | E23: 57 | F23: 1 413 | G23: 38.34
A24: 214Pb | B24: 351.881 | C24: 2 438 | D24: 78 | E24: 66 | F24: 2 373 | G24: 49.38
A25: 214Bi | B25: 609.176 | C25: 839 | D25: 47 | E25: 42 | F25: 797 | G25: 28.97
A26: 137Cs | B26: 661.617 | C26: 2 579 | D26: 55 | E26: 33 | F26: 2 537 | G26: 50.78
A27: 40K | B27: 1460.19 | C27: 1 128 | D27: 29 | E27: 16 | F27: 1 106 | G27: 33.59
A28: 214Bi | B28: 1121.17 | C28: 160 | D28: 23 | E28: 36 | F28: 131 | G28: 12.65
A29: 228Ac | B29: 1775.39 | C29: 9 | D29: 24 | E29: 13 | F29: -8 | G29: 3
A30: 234Th | B30: 63.3618 | C30: 2 200 | D30: 266 | E30: 263 | F30: 1 961 | G30: 46.9
A31: 226Ra | B31: 185.848 | C31: 1 922 | D31: 127 | E31: 110 | F31: 1 817 | G31: 43.84
A32: 212Pb | B32: 238.567 | C32: 1 676 | D32: 110 | E32: 89 | F32: 1 583 | G32: 40.94
A33: 208Tl | B33: 582.956 | C33: 249 | D33: 43 | E33: 57 | F33: 202 | G33: 15.78
A34: 228Ac | B34: 338.076 | C34: 301 | D34: 69 | E34: 53 | F34: 245 | G34: 17.35
A35: 228Ac | B35: 910.852 | C35: 290 | D35: 39 | E35: 38 | F35: 253 | G35: 17.03
A36: 228Ac | B36: 968.852 | C36: 179 | D36: 30 | E36: 30 | F36: 150 | G36: 13.38
A37: 235U | B37: 143.691 | C37: 481 | D37: 128 | E37: 141 | F37: 324 | G37: 21.93

Sheet 2
A1: NOM | B1: Nucleide | C1: E kev | D1: Canaux | E1: %emis | F1: Rendement | G1: temps | H1: poids | I1: bdf | J1: eff | K1: pic1 | L1: bdfg | M1: bdfd | O1: pic net | Q1: cpm | S1: dpm/g | V1: Bq/k | X1: Data Certif
A2: RGU | B2: 210Pb | C2: 46.5 | D2: 9 | E2: 0.04 | F2: 0.535 | G2: =259009/60 -> 4316.8167 | H2: =2.86-1.78 -> 1.08 | I2: 0 | J2: 0.0214 | K2: 11133 | L2: 1005 | M2: 737 | N2: =K2-(L2+M2)/2 -> 10262 | O2: ± | P2: =SQRT((K2+(L2+M2)/2)) -> 109.56277 | Q2: =N2/G2 -> 2.3772147 | R2: =(Q2/H2/J2) -> 102.8563 | S2: ± | T2: =P2/N2*R2 -> 1.0981505 | U2: =R2/60*1000 -> 1714.2716 | V2: ± | W2: =T2/R2*U2 -> 18.302508 | X2: 4940
A3: IAEA447 | B3: 241Am | C3: 59.5 | D3: 8 | E3: 0.363 | F3: 0.71625344 | G3: =G2 -> 4316.8167 | H3: =H2 -> 1.08 | I3: 0 | J3: 0.26 | K3: 846 | L3: 572 | M3: 602 | N3: =K3-(L3+M3)/2 -> 259 | O3: ± | P3: =SQRT((K3+(L3+M3)/2)) -> 37.854986 | Q3: =N3/G3 -> 0.059997915 | R3: =Q3/H3/J3 -> 0.21366779 | S3: ± | T3: =P3/N3*R3 -> 0.03122931 | U3: =R3/60*1000 -> 3.5611298 | V3: ± | W3: =T3/R3*U3 -> 0.5204885 | X3: 2.15
A4: RGU1 | B4: 214Bi | C4: 295 | D4: 11 | E4: 0.192 | F4: 0.421875 | G4: =G2 -> 4316.8167 | H4: =H2 -> 1.08 | J4: 0.081 | K4: 4673 | L4: 240 | M4: 205 | N4: =K4-(L4+M4)/2 -> 4450.5 | O4: ± | P4: =SQRT((K4+(L4+M4)/2)) -> 69.96785 | Q4: =N4/G4 -> 1.030968 | R4: =(Q4/H4/J4) -> 11.785186 | S4: ± | T4: =P4/N4*R4 -> 0.18527898 | U4: =R4/60*1000 -> 196.41976 | V4: ± | W4: =T4/R4*U4 -> 3.087983 | X4: 4940
A5: RGU1 | B5: 214Bi | C5: 352 | D5: 12 | E5: 0.371 | F5: 0.36927224 | G5: =G2 -> 4316.8167 | H5: =H2 -> 1.08 | I5: 0.002 | J5: 0.137 | K5: 7668 | L5: 290 | M5: 205 | N5: =K5-(L5+M5)/2 -> 7420.5 | O5: ± | P5: =SQRT((K5+(L5+M5)/2)) -> 88.969096 | Q5: =N5/G5 -> 1.718975 | R5: =(Q5/H5/J5) -> 11.617836 | S5: ± | T5: =P5/N5*R5 -> 0.13929363 | U5: =R5/60*1000 -> 193.6306 | V5: ± | W5: =T5/R5*U5 -> 2.3215605 | X5: 4940
A6: RGU1 | B6: 214Bi | C6: 609 | D6: 16 | E6: 0.461 | F6: 0.09978308 | G6: =G2 -> 4316.8167 | H6: =H2 -> 1.08 | I6: 0.002 | J6: 0.046 | K6: 2665 | L6: 166 | M6: 162 | N6: =K6-(L6+M6)/2 -> 2501 | O6: ± | P6: =SQRT((K6+(L6+M6)/2)) -> 53.188345 | Q6: =N6/G6 -> 0.57936211 | R6: =(Q6/H6/J6) -> 11.661878 | S6: ± | T6: =P6/N6*R6 -> 0.24801119 | U6: =R6/60*1000 -> 194.36464 | V6: ± | W6: =T6/R6*U6 -> 4.1335199 | X6: 4940
A7: IAEA447 | B7: 137Cs | C7: 661 | D7: 20 | E7: 0.8462 | F7: 0.29189317 | G7: =G2 -> 4316.8167 | H7: =H2 -> 1.08 | I7: 0.001 | J7: 0.247 | K7: 10456 | L7: 185 | M7: 155 | N7: =K7-(L7+M7)/2 -> 10286 | O7: ± | P7: =SQRT((K7+(L7+M7)/2)) -> 103.08249 | Q7: =N7/G7 -> 2.3827743 | R7: =Q7/H7/J7 -> 8.9322775 | S7: ± | T7: =P7/N7*R7 -> 0.089515984 | U7: =R7/60*1000 -> 148.87129 | V7: ± | W7: =T7/R7*U7 -> 1.4919331 | X7: 335
A8: RGU | B8: 40K | C8: 1460 | D8: 20 | E8: 0.107 | F8: 0.14485981 | G8: =G2 -> 4316.8167 | H8: =H2 -> 1.08 | I8: 0.004 | J8: 0.0155 | K8: 3242 | L8: 72 | M8: 67 | N8: =K8-(L8+M8)/2 -> 3172.5 | O8: ± | P8: =SQRT((K8+(L8+M8)/2)) -> 57.545634 | Q8: =N8/G8 -> 0.73491655 | R8: =Q8/H8/J8 -> 43.901825 | S8: ± | T8: =P8/N8*R8 -> 0.79633045 | U8: =R8/60*1000 -> 731.69708 | V8: ± | W8: =T8/R8*U8 -> 13.272174 | X8: 550
A9: RGTh | B9: 212Pb | C9: 238 | D9: 11 | E9: 0.431 | G9: =G3 -> 4316.8167 | H9: =H2 -> 1.08 | J9: 0.19 | K9: 5260 | L9: 368 | M9: 304 | N9: =K9-(L9+M9)/2 -> 4924 | P9: =SQRT((K9+(L9+M9)/2)) -> 74.806417 | Q9: =N9/G9 -> 1.1406553 | R9: =Q9/H9/J9 -> 5.5587492 | S9: ± | T9: =P9/N9*R9 -> 0.084449657 | U9: =R9/60*1000 -> 92.645821 | V9: ± | W9: =T9/R9*U9 -> 1.4074943
A10: RGTh | B10: 208Tl | C10: 583 | D10: 13 | G10: =G4 -> 4316.8167 | H10: =H2 -> 1.08 | J10: 0.025 | K10: 729 | L10: 134 | M10: 141 | N10: =K10-(L10+M10)/2 -> 591.5 | P10: =SQRT((K10+(L10+M10)/2)) -> 29.436372 | Q10: =N10/G10 -> 0.13702227 | R10: =Q10/H10/J10 -> 5.0748987 | S10: ± | T10: =P10/N10*R10 -> 0.25255555 | U10: =R10/60*1000 -> 84.581645 | V10: ± | W10: =T10/R10*U10 -> 4.2092591
A11: RGTh | B11: 228Ac | C11: 338 | D11: 16 | E11: 0.12 | G11: =G3 -> 4316.8167 | H11: =H2 -> 1.08 | J11: 0.031 | K11: 955 | L11: 207 | M11: 205 | N11: =K11-(L11+M11)/2 -> 749 | P11: =SQRT((K11+(L11+M11)/2)) -> 34.07345 | Q11: =N11/G11 -> 0.17350748 | R11: =Q11/H11/J11 -> 5.1824219 | S11: ± | T11: =P11/N11*R11 -> 0.23575834 | U11: =R11/60*1000 -> 86.373698 | V11: ± | W11: =T11/R11*U11 -> 3.9293056
A12: RGTh | B12: 228Ac | C12: 911 | D12: 20 | E12: 0.29 | G12: =G2 -> 4316.8167 | H12: =H2 -> 1.08 | J12: 0.03 | K12: 874 | L12: 121 | M12: 122 | N12: =K12-(L12+M12)/2 -> 752.5 | P12: =SQRT((K12+(L12+M12)/2)) -> 31.551545 | Q12: =N12/G12 -> 0.17431827 | R12: =Q12/H12/J12 -> 5.3801934 | S12: ± | T12: =P12/N12*R12 -> 0.22558593 | U12: =R12/60*1000 -> 89.66989 | V12: ± | W12: =T12/R12*U12 -> 3.7597656
A13: RGTh | B13: 228Ac | C13: 968 | D13: 14 | E13: 0.18 | G13: =G3 -> 4316.8167 | H13: =H2 -> 1.08 | J13: 0.018 | K13: 534 | L13: 93 | M13: 97 | N13: =K13-(L13+M13)/2 -> 439 | P13: =SQRT((K13+(L13+M13)/2)) -> 25.079872 | Q13: =N13/G13 -> 0.10169531 | R13: =Q13/H13/J13 -> 5.2312401 | S13: ± | T13: =P13/N13*R13 -> 0.29885839 | U13: =R13/60*1000 -> 87.187335 | V13: ± | W13: =T13/R13*U13 -> 4.9809732
B14: Somme 226Ra | G14: =G2 -> 4316.8167 | H14: =H2 -> 1.08 | I14: 0.005 | J14: =J4+J5+J6 -> 0.264 | K14: =K4+K5+K6 -> 15006 | L14: =L4+L5+L6 -> 696 | M14: =M4+M5+M6 -> 572 | N14: =N4+N5+N6 -> 14372 | O14: ± | P14: =SQRT((K14+(L14+M14)/2)) -> 125.05999 | Q14: =N14/G14 -> 3.3293052 | R14: =(Q14/H14/J14) -> 11.676856 | S14: ± | T14: =P14/N14*R14 -> 0.10160781 | U14: =R14/60*1000 -> 194.61427 | V14: ± | W14: =T14/R14*U14 -> 1.6934635
B15: Somme 228Th | G15: =G14 -> 4316.8167 | H15: =H14 -> 1.08 | I15: 0.005 | J15: =J9+J10 -> 0.215 | K15: =K9+K10 -> 5989 | L15: =L9+L10 -> 502 | M15: =M9+M10 -> 445 | N15: =N9+N10 -> 5515.5 | O15: ± | P15: =SQRT((K15+(L15+M15)/2)) -> 80.389676 | Q15: =N15/G15 -> 1.2776776 | R15: =(Q15/H15/J15) -> 5.5024876 | S15: ± | T15: =P15/N15*R15 -> 0.080200017 | U15: =R15/60*1000 -> 91.708126 | V15: ± | W15: =T15/R15*U15 -> 1.3366669 | X15: 3225
B16: Somme 228Ra | G16: =G10 -> 4316.8167 | H16: =H10 -> 1.08 | I16: 0.005 | J16: =J11+J12+J13 -> 0.079 | K16: =K11+K12+K13 -> 2363 | L16: =L11+L12+L13 -> 421 | M16: =M11+M12+M13 -> 424 | N16: =N11+N12+N13 -> 1940.5 | O16: ± | P16: =SQRT((K16+(L16+M16)/2)) -> 52.777836 | Q16: =N16/G16 -> 0.44952106 | R16: =(Q16/H16/J16) -> 5.2686481 | S16: ± | T16: =P16/N16*R16 -> 0.14329701 | U16: =R16/60*1000 -> 87.810802 | V16: ± | W16: =T16/R16*U16 -> 2.3882835 | X16: 3225
A18: NOI_2 | B18: 259 009,000
A20: Isotope | B20: Energie(Kev) | C20: Somme pic | D20: Somme bkg gauche | E20: Somme bkg droit | F20: Somme-bkg | G20: Sigma
A21: 210Pb | B21: 46.4991 | C21: 11 133 | D21: 1 005 | E21: 737 | F21: 10 349 | G21: 105.51
A22: 241Am | B22: 59.7484 | C22: 846 | D22: 572 | E22: 602 | F22: 324 | G22: 29.09
A23: 214Pb | B23: 295.178 | C23: 4 673 | D23: 240 | E23: 205 | F23: 4 469 | G23: 68.36
A24: 214Pb | B24: 351.881 | C24: 7 668 | D24: 290 | E24: 205 | F24: 7 447 | G24: 87.57
A25: 214Bi | B25: 609.176 | C25: 2 665 | D25: 166 | E25: 162 | F25: 2 510 | G25: 51.62
A26: 137Cs | B26: 661.617 | C26: 10 456 | D26: 185 | E26: 155 | F26: 10 294 | G26: 102.25
A27: 40K | B27: 1460.19 | C27: 3 242 | D27: 72 | E27: 67 | F27: 3 175 | G27: 56.94
A28: 214Bi | B28: 1121.17 | C28: 401 | D28: 94 | E28: 85 | F28: 315 | G28: 20.02
A29: 228Ac | B29: 1775.39 | C29: 26 | D29: 60 | E29: 41 | F29: -22 | G29: 5.1
A30: 234Th | B30: 63.3618 | C30: 7 196 | D30: 827 | E30: 813 | F30: 6 458 | G30: 84.83
A31: 226Ra | B31: 185.848 | C31: 5 936 | D31: 419 | E31: 303 | F31: 5 619 | G31: 77.05
A32: 212Pb | B32: 238.567 | C32: 5 260 | D32: 368 | E32: 304 | F32: 4 946 | G32: 72.53
A33: 208Tl | B33: 582.956 | C33: 729 | D33: 134 | E33: 141 | F33: 600 | G33: 27
A34: 228Ac | B34: 338.076 | C34: 955 | D34: 207 | E34: 205 | F34: 767 | G34: 30.9
A35: 228Ac | B35: 910.852 | C35: 874 | D35: 121 | E35: 122 | F35: 758 | G35: 29.56
A36: 228Ac | B36: 968.852 | C36: 534 | D36: 93 | E36: 97 | F36: 444 | G36: 23.11
A37: 235U | B37: 143.691 | C37: 1 488 | D37: 445 | E37: 402 | F37: 993 | G37: 38.57

Sheet 3
A1: NOM | B1: Nucleide | C1: E kev | D1: Canaux | E1: %emis | F1: Rendement | G1: temps | H1: poids | I1: bdf | J1: eff | K1: pic1 | L1: bdfg | M1: bdfd | O1: pic net | Q1: cpm | S1: dpm/g | V1: Bq/k | X1: Data Certif
A2: RGU | B2: 210Pb | C2: 46.5 | D2: 9 | E2: 0.04 | F2: 0.535 | G2: =334375/60 -> 5572.9167 | H2: =2.95-1.79 -> 1.16 | I2: 0 | J2: 0.0214 | K2: 16511 | L2: 1358 | M2: 1080 | N2: =K2-(L2+M2)/2 -> 15292 | O2: ± | P2: =SQRT((K2+(L2+M2)/2)) -> 133.15405 | Q2: =N2/G2 -> 2.743985 | R2: =(Q2/H2/J2) -> 110.53759 | S2: ± | T2: =P2/N2*R2 -> 0.96249849 | U2: =R2/60*1000 -> 1842.2931 | V2: ± | W2: =T2/R2*U2 -> 16.041641 | X2: 4940
A3: IAEA447 | B3: 241Am | C3: 59.5 | D3: 8 | E3: 0.363 | F3: 0.71625344 | G3: =G2 -> 5572.9167 | H3: =H2 -> 1.16 | I3: 0 | J3: 0.26 | K3: 1263 | L3: 815 | M3: 843 | N3: =K3-(L3+M3)/2 -> 434 | O3: ± | P3: =SQRT((K3+(L3+M3)/2)) -> 45.738387 | Q3: =N3/G3 -> 0.077876636 | R3: =Q3/H3/J3 -> 0.25821166 | S3: ± | T3: =P3/N3*R3 -> 0.027212407 | U3: =R3/60*1000 -> 4.3035276 | V3: ± | W3: =T3/R3*U3 -> 0.45354011 | X3: 2.15
A4: RGU1 | B4: 214Bi | C4: 295 | D4: 11 | E4: 0.192 | F4: 0.421875 | G4: =G2 -> 5572.9167 | H4: =H2 -> 1.16 | J4: 0.081 | K4: 6424 | L4: 345 | M4: 299 | N4: =K4-(L4+M4)/2 -> 6102 | O4: ± | P4: =SQRT((K4+(L4+M4)/2)) -> 82.134037 | Q4: =N4/G4 -> 1.0949383 | R4: =(Q4/H4/J4) -> 11.653239 | S4: ± | T4: =P4/N4*R4 -> 0.15685473 | U4: =R4/60*1000 -> 194.22065 | V4: ± | W4: =T4/R4*U4 -> 2.6142455 | X4: 4940
A5: RGU1 | B5: 214Bi | C5: 352 | D5: 12 | E5: 0.371 | F5: 0.36927224 | G5: =G2 -> 5572.9167 | H5: =H2 -> 1.16 | I5: 0.002 | J5: 0.137 | K5: 10519 | L5: 351 | M5: 304 | N5: =K5-(L5+M5)/2 -> 10191.5 | O5: ± | P5: =SQRT((K5+(L5+M5)/2)) -> 104.14653 | Q5: =N5/G5 -> 1.8287551 | R5: =(Q5/H5/J5) -> 11.507395 | S5: ± | T5: =P5/N5*R5 -> 0.11759361 | U5: =R5/60*1000 -> 191.78991 | V5: ± | W5: =T5/R5*U5 -> 1.9598934 | X5: 4940
A6: RGU1 | B6: 214Bi | C6: 609 | D6: 16 | E6: 0.461 | F6: 0.09978308 | G6: =G2 -> 5572.9167 | H6: =H2 -> 1.16 | I6: 0.002 | J6: 0.046 | K6: 3640 | L6: 202 | M6: 200 | N6: =K6-(L6+M6)/2 -> 3439 | O6: ± | P6: =SQRT((K6+(L6+M6)/2)) -> 61.975802 | Q6: =N6/G6 -> 0.61709159 | R6: =(Q6/H6/J6) -> 11.564685 | S6: ± | T6: =P6/N6*R6 -> 0.20841251 | U6: =R6/60*1000 -> 192.74475 | V6: ± | W6: =T6/R6*U6 -> 3.4735418 | X6: 4940
A7: IAEA447 | B7: 137Cs | C7: 661 | D7: 20 | E7: 0.8462 | F7: 0.29189317 | G7: =G2 -> 5572.9167 | H7: =H2 -> 1.16 | I7: 0.001 | J7: 0.247 | K7: 16605 | L7: 269 | M7: 206 | N7: =K7-(L7+M7)/2 -> 16367.5 | O7: ± | P7: =SQRT((K7+(L7+M7)/2)) -> 129.77866 | Q7: =N7/G7 -> 2.936972 | R7: =Q7/H7/J7 -> 10.250495 | S7: ± | T7: =P7/N7*R7 -> 0.081276648 | U7: =R7/60*1000 -> 170.84159 | V7: ± | W7: =T7/R7*U7 -> 1.3546108 | X7: 335
A8: RGU | B8: 40K | C8: 1460 | D8: 20 | E8: 0.107 | F8: 0.14485981 | G8: =G2 -> 5572.9167 | H8: =H2 -> 1.16 | I8: 0.004 | J8: 0.0155 | K8: 4394 | L8: 89 | M8: 97 | N8: =K8-(L8+M8)/2 -> 4301 | O8: ± | P8: =SQRT((K8+(L8+M8)/2)) -> 66.985073 | Q8: =N8/G8 -> 0.77176822 | R8: =Q8/H8/J8 -> 42.923705 | S8: ± | T8: =P8/N8*R8 -> 0.66850675 | U8: =R8/60*1000 -> 715.39509 | V8: ± | W8: =T8/R8*U8 -> 11.141779 | X8: 550
A9: RGTh | B9: 212Pb | C9: 238 | D9: 11 | E9: 0.431 | G9: =G3 -> 5572.9167 | H9: =H2 -> 1.16 | J9: 0.19 | K9: 7387 | L9: 572 | M9: 478 | N9: =K9-(L9+M9)/2 -> 6862 | P9: =SQRT((K9+(L9+M9)/2)) -> 88.949424 | Q9: =N9/G9 -> 1.2313121 | R9: =Q9/H9/J9 -> 5.5867157 | S9: ± | T9: =P9/N9*R9 -> 0.072418412 | U9: =R9/60*1000 -> 93.111929 | V9: ± | W9: =T9/R9*U9 -> 1.2069735
A10: RGTh | B10: 208Tl | C10: 583 | D10: 13 | G10: =G4 -> 5572.9167 | H10: =H2 -> 1.16 | J10: 0.025 | K10: 1039 | L10: 188 | M10: 170 | N10: =K10-(L10+M10)/2 -> 860 | P10: =SQRT((K10+(L10+M10)/2)) -> 34.899857 | Q10: =N10/G10 -> 0.15431776 | R10: =Q10/H10/J10 -> 5.321302 | S10: ± | T10: =P10/N10*R10 -> 0.21594497 | U10: =R10/60*1000 -> 88.688366 | V10: ± | W10: =T10/R10*U10 -> 3.5990829
A11: RGTh | B11: 228Ac | C11: 338 | D11: 16 | E11: 0.12 | G11: =G3 -> 5572.9167 | H11: =H2 -> 1.16 | J11: 0.031 | K11: 1292 | L11: 288 | M11: 273 | N11: =K11-(L11+M11)/2 -> 1011.5 | P11: =SQRT((K11+(L11+M11)/2)) -> 39.65476 | Q11: =N11/G11 -> 0.1815028 | R11: =Q11/H11/J11 -> 5.0473527 | S11: ± | T11: =P11/N11*R11 -> 0.19787599 | U11: =R11/60*1000 -> 84.122545 | V11: ± | W11: =T11/R11*U11 -> 3.2979331
A12: RGTh | B12: 228Ac | C12: 911 | D12: 20 | E12: 0.29 | G12: =G2 -> 5572.9167 | H12: =H2 -> 1.16 | J12: 0.03 | K12: 1155 | L12: 142 | M12: 159 | N12: =K12-(L12+M12)/2 -> 1004.5 | P12: =SQRT((K12+(L12+M12)/2)) -> 36.131704 | Q12: =N12/G12 -> 0.18024673 | R12: =Q12/H12/J12 -> 5.1795037 | S12: ± | T12: =P12/N12*R12 -> 0.18630592 | U12: =R12/60*1000 -> 86.325062 | V12: ± | W12: =T12/R12*U12 -> 3.1050986
A13: RGTh | B13: 228Ac | C13: 968 | D13: 14 | E13: 0.18 | G13: =G3 -> 5572.9167 | H13: =H2 -> 1.16 | J13: 0.018 | K13: 764 | L13: 137 | M13: 140 | N13: =K13-(L13+M13)/2 -> 625.5 | P13: =SQRT((K13+(L13+M13)/2)) -> 30.041638 | Q13: =N13/G13 -> 0.11223925 | R13: =Q13/H13/J13 -> 5.3754431 | S13: ± | T13: =P13/N13*R13 -> 0.25817285 | U13: =R13/60*1000 -> 89.590719 | V13: ± | W13: =T13/R13*U13 -> 4.3028808
B14: Somme 226Ra | G14: =G2 -> 5572.9167 | H14: =H2 -> 1.16 | I14: 0.005 | J14: =J4+J5+J6 -> 0.264 | K14: =K4+K5+K6 -> 20583 | L14: =L4+L5+L6 -> 898 | M14: =M4+M5+M6 -> 803 | N14: =N4+N5+N6 -> 19732.5 | O14: ± | P14: =SQRT((K14+(L14+M14)/2)) -> 146.40184 | Q14: =N14/G14 -> 3.540785 | R14: =(Q14/H14/J14) -> 11.562125 | S14: ± | T14: =P14/N14*R14 -> 0.085783168 | U14: =R14/60*1000 -> 192.70208 | V14: ± | W14: =T14/R14*U14 -> 1.4297195
B15: Somme 228Th | G15: =G14 -> 5572.9167 | H15: =H14 -> 1.16 | I15: 0.005 | J15: =J9+J10 -> 0.215 | K15: =K9+K10 -> 8426 | L15: =L9+L10 -> 760 | M15: =M9+M10 -> 648 | N15: =N9+N10 -> 7722 | O15: ± | P15: =SQRT((K15+(L15+M15)/2)) -> 95.551033 | Q15: =N15/G15 -> 1.3856299 | R15: =(Q15/H15/J15) -> 5.5558537 | S15: ± | T15: =P15/N15*R15 -> 0.068747418 | U15: =R15/60*1000 -> 92.597561 | V15: ± | W15: =T15/R15*U15 -> 1.1457903 | X15: 3225
B16: Somme 228Ra | G16: =G10 -> 5572.9167 | H16: =H10 -> 1.16 | I16: 0.005 | J16: =J11+J12+J13 -> 0.079 | K16: =K11+K12+K13 -> 3211 | L16: =L11+L12+L13 -> 567 | M16: =M11+M12+M13 -> 572 | N16: =N11+N12+N13 -> 2641.5 | O16: ± | P16: =SQRT((K16+(L16+M16)/2)) -> 61.485771 | Q16: =N16/G16 -> 0.47398879 | R16: =(Q16/H16/J16) -> 5.1722914 | S16: ± | T16: =P16/N16*R16 -> 0.1203946 | U16: =R16/60*1000 -> 86.204857 | V16: ± | W16: =T16/R16*U16 -> 2.0065766 | X16: 3225
A18: NOI_3 | B18: 334 375,000
A20: Isotope | B20: Energie(Kev) | C20: Somme pic | D20: Somme bkg gauche | E20: Somme bkg droit | F20: Somme-bkg | G20: Sigma
A21: 210Pb | B21: 46.4991 | C21: 16 511 | D21: 1 358 | E21: 1 080 | F21: 15 413 | G21: 128.5
A22: 241Am | B22: 59.7484 | C22: 1 263 | D22: 815 | E22: 843 | F22: 526 | G22: 35.54
A23: 214Pb | B23: 295.178 | C23: 6 424 | D23: 345 | E23: 299 | F23: 6 128 | G23: 80.15
A24: 214Pb | B24: 351.881 | C24: 10 519 | D24: 351 | E24: 304 | F24: 10 225 | G24: 102.56
A25: 214Bi | B25: 609.176 | C25: 3 640 | D25: 202 | E25: 200 | F25: 3 450 | G25: 60.33
A26: 137Cs | B26: 661.617 | C26: 16 605 | D26: 269 | E26: 206 | F26: 16 380 | G26: 128.86
A27: 40K | B27: 1460.19 | C27: 4 394 | D27: 89 | E27: 97 | F27: 4 304 | G27: 66.29
A28: 214Bi | B28: 1121.17 | C28: 594 | D28: 135 | E28: 151 | F28: 457 | G28: 24.37
A29: 228Ac | B29: 1775.39 | C29: 24 | D29: 74 | E29: 33 | F29: -27 | G29: 4.9
A30: 234Th | B30: 63.3618 | C30: 10 063 | D30: 1 121 | E30: 1 110 | F30: 9 059 | G30: 100.31
A31: 226Ra | B31: 185.848 | C31: 8 241 | D31: 587 | E31: 507 | F31: 7 760 | G31: 90.78
A32: 212Pb | B32: 238.567 | C32: 7 387 | D32: 572 | E32: 478 | F32: 6 897 | G32: 85.95
A33: 208Tl | B33: 582.956 | C33: 1 039 | D33: 188 | E33: 170 | F33: 871 | G33: 32.23
A34: 228Ac | B34: 338.076 | C34: 1 292 | D34: 288 | E34: 273 | F34: 1 037 | G34: 35.94
A35: 228Ac | B35: 910.852 | C35: 1 155 | D35: 142 | E35: 159 | F35: 1 011 | G35: 33.99
A36: 228Ac | B36: 968.852 | C36: 764 | D36: 137 | E36: 140 | F36: 632 | G36: 27.64
A37: 235U | B37: 143.691 | C37: 2 166 | D37: 601 | E37: 576 | F37: 1 479 | G37: 46.54

Sheet 4
A1: NOM | B1: Nucleide | C1: E kev | D1: Canaux | E1: %emis | F1: Rendement | G1: temps | H1: poids | I1: bdf | J1: eff | K1: pic1 | L1: bdfg | M1: bdfd | O1: pic net | Q1: cpm | S1: dpm/g | V1: Bq/k | X1: Data Certif
A2: RGU | B2: 210Pb | C2: 46.5 | D2: 9 | E2: 0.04 | F2: 0.535 | G2: =79498/60 -> 1324.9667 | H2: =2.92-1.77 -> 1.15 | I2: 0 | J2: 0.0214 | K2: 4202 | L2: 330 | M2: 251 | N2: =K2-(L2+M2)/2 -> 3911.5 | O2: ± | P2: =SQRT((K2+(L2+M2)/2)) -> 67.026114 | Q2: =N2/G2 -> 2.9521497 | R2: =(Q2/H2/J2) -> 119.95732 | S2: ± | T2: =P2/N2*R2 -> 2.0555473 | U2: =R2/60*1000 -> 1999.2887 | V2: ± | W2: =T2/R2*U2 -> 34.259122 | X2: 4940
A3: IAEA447 | B3: 241Am | C3: 59.5 | D3: 8 | E3: 0.363 | F3: 0.71625344 | G3: =G2 -> 1324.9667 | H3: =H2 -> 1.15 | I3: 0 | J3: 0.26 | K3: 294 | L3: 197 | M3: 194 | N3: =K3-(L3+M3)/2 -> 98.5 | O3: ± | P3: =SQRT((K3+(L3+M3)/2)) -> 22.124647 | Q3: =N3/G3 -> 0.074341493 | R3: =Q3/H3/J3 -> 0.24863376 | S3: ± | T3: =P3/N3*R3 -> 0.055847046 | U3: =R3/60*1000 -> 4.1438959 | V3: ± | W3: =T3/R3*U3 -> 0.9307841 | X3: 2.15
A4: RGU1 | B4: 214Bi | C4: 295 | D4: 11 | E4: 0.192 | F4: 0.421875 | G4: =G2 -> 1324.9667 | H4: =H2 -> 1.15 | J4: 0.081 | K4: 1466 | L4: 91 | M4: 58 | N4: =K4-(L4+M4)/2 -> 1391.5 | O4: ± | P4: =SQRT((K4+(L4+M4)/2)) -> 39.249204 | Q4: =N4/G4 -> 1.0502151 | R4: =(Q4/H4/J4) -> 11.274451 | S4: ± | T4: =P4/N4*R4 -> 0.31801166 | U4: =R4/60*1000 -> 187.90751 | V4: ± | W4: =T4/R4*U4 -> 5.3001943 | X4: 4940
A5: RGU1 | B5: 214Bi | C5: 352 | D5: 12 | E5: 0.371 | F5: 0.36927224 | G5: =G2 -> 1324.9667 | H5: =H2 -> 1.15 | I5: 0.002 | J5: 0.137 | K5: 2570 | L5: 88 | M5: 79 | N5: =K5-(L5+M5)/2 -> 2486.5 | O5: ± | P5: =SQRT((K5+(L5+M5)/2)) -> 51.512134 | Q5: =N5/G5 -> 1.876651 | R5: =(Q5/H5/J5) -> 11.911463 | S5: ± | T5: =P5/N5*R5 -> 0.24676649 | U5: =R5/60*1000 -> 198.52438 | V5: ± | W5: =T5/R5*U5 -> 4.1127749 | X5: 4940
A6: RGU1 | B6: 214Bi | C6: 609 | D6: 16 | E6: 0.461 | F6: 0.09978308 | G6: =G2 -> 1324.9667 | H6: =H2 -> 1.15 | I6: 0.002 | J6: 0.046 | K6: 823 | L6: 42 | M6: 51 | N6: =K6-(L6+M6)/2 -> 776.5 | O6: ± | P6: =SQRT((K6+(L6+M6)/2)) -> 29.487285 | Q6: =N6/G6 -> 0.58605248 | R6: =(Q6/H6/J6) -> 11.078497 | S6: ± | T6: =P6/N6*R6 -> 0.4207016 | U6: =R6/60*1000 -> 184.64161 | V6: ± | W6: =T6/R6*U6 -> 7.0116934 | X6: 4940
A7: IAEA447 | B7: 137Cs | C7: 661 | D7: 20 | E7: 0.8462 | F7: 0.29189317 | G7: =G2 -> 1324.9667 | H7: =H2 -> 1.15 | I7: 0.001 | J7: 0.247 | K7: 3933 | L7: 63 | M7: 46 | N7: =K7-(L7+M7)/2 -> 3878.5 | O7: ± | P7: =SQRT((K7+(L7+M7)/2)) -> 63.146655 | Q7: =N7/G7 -> 2.9272435 | R7: =Q7/H7/J7 -> 10.305381 | S7: ± | T7: =P7/N7*R7 -> 0.16778402 | U7: =R7/60*1000 -> 171.75635 | V7: ± | W7: =T7/R7*U7 -> 2.7964004 | X7: 335
A8: RGU | B8: 40K | C8: 1460 | D8: 20 | E8: 0.107 | F8: 0.14485981 | G8: =G2 -> 1324.9667 | H8: =H2 -> 1.15 | I8: 0.004 | J8: 0.0155 | K8: 1047 | L8: 22 | M8: 23 | N8: =K8-(L8+M8)/2 -> 1024.5 | O8: ± | P8: =SQRT((K8+(L8+M8)/2)) -> 32.703211 | Q8: =N8/G8 -> 0.773227 | R8: =Q8/H8/J8 -> 43.378794 | S8: ± | T8: =P8/N8*R8 -> 1.3847007 | U8: =R8/60*1000 -> 722.9799 | V8: ± | W8: =T8/R8*U8 -> 23.078345 | X8: 550
A9: RGTh | B9: 212Pb | C9: 238 | D9: 11 | E9: 0.431 | G9: =G3 -> 1324.9667 | H9: =H2 -> 1.15 | J9: 0.19 | K9: 1724 | L9: 119 | M9: 119 | N9: =K9-(L9+M9)/2 -> 1605 | P9: =SQRT((K9+(L9+M9)/2)) -> 42.930176 | Q9: =N9/G9 -> 1.2113512 | R9: =Q9/H9/J9 -> 5.5439416 | S9: ± | T9: =P9/N9*R9 -> 0.14828809 | U9: =R9/60*1000 -> 92.399026 | V9: ± | W9: =T9/R9*U9 -> 2.4714682
A10: RGTh | B10: 208Tl | C10: 583 | D10: 13 | G10: =G4 -> 1324.9667 | H10: =H2 -> 1.15 | J10: 0.025 | K10: 258 | L10: 50 | M10: 39 | N10: =K10-(L10+M10)/2 -> 213.5 | P10: =SQRT((K10+(L10+M10)/2)) -> 17.392527 | Q10: =N10/G10 -> 0.16113613 | R10: =Q10/H10/J10 -> 5.6047349 | S10: ± | T10: =P10/N10*R10 -> 0.45658316 | U10: =R10/60*1000 -> 93.412249 | V10: ± | W10: =T10/R10*U10 -> 7.6097193
A11: RGTh | B11: 228Ac | C11: 338 | D11: 16 | E11: 0.12 | G11: =G3 -> 1324.9667 | H11: =H2 -> 1.15 | J11: 0.031 | K11: 319 | L11: 70 | M11: 69 | N11: =K11-(L11+M11)/2 -> 249.5 | P11: =SQRT((K11+(L11+M11)/2)) -> 19.710403 | Q11: =N11/G11 -> 0.18830662 | R11: =Q11/H11/J11 -> 5.2820932 | S11: ± | T11: =P11/N11*R11 -> 0.41728332 | U11: =R11/60*1000 -> 88.034887 | V11: ± | W11: =T11/R11*U11 -> 6.954722
A12: RGTh | B12: 228Ac | C12: 911 | D12: 20 | E12: 0.29 | G12: =G2 -> 1324.9667 | H12: =H2 -> 1.15 | J12: 0.03 | K12: 238 | L12: 40 | M12: 40 | N12: =K12-(L12+M12)/2 -> 198 | P12: =SQRT((K12+(L12+M12)/2)) -> 16.673332 | Q12: =N12/G12 -> 0.14943772 | R12: =Q12/H12/J12 -> 4.3315282 | S12: ± | T12: =P12/N12*R12 -> 0.36475256 | U12: =R12/60*1000 -> 72.192136 | V12: ± | W12: =T12/R12*U12 -> 6.0792094
A13: RGTh | B13: 228Ac | C13: 968 | D13: 14 | E13: 0.18 | G13: =G3 -> 1324.9667 | H13: =H2 -> 1.15 | J13: 0.018 | K13: 189 | L13: 27 | M13: 28 | N13: =K13-(L13+M13)/2 -> 161.5 | P13: =SQRT((K13+(L13+M13)/2)) -> 14.713939 | Q13: =N13/G13 -> 0.12188986 | R13: =Q13/H13/J13 -> 5.888399 | S13: ± | T13: =P13/N13*R13 -> 0.53648014 | U13: =R13/60*1000 -> 98.139983 | V13: ± | W13: =T13/R13*U13 -> 8.9413357
B14: Somme 226Ra | G14: =G2 -> 1324.9667 | H14: =H2 -> 1.15 | I14: 0.005 | J14: =J4+J5+J6 -> 0.264 | K14: =K4+K5+K6 -> 4859 | L14: =L4+L5+L6 -> 221 | M14: =M4+M5+M6 -> 188 | N14: =N4+N5+N6 -> 4654.5 | O14: ± | P14: =SQRT((K14+(L14+M14)/2)) -> 71.158274 | Q14: =N14/G14 -> 3.5129186 | R14: =(Q14/H14/J14) -> 11.570878 | S14: ± | T14: =P14/N14*R14 -> 0.17689627 | U14: =R14/60*1000 -> 192.84797 | V14: ± | W14: =T14/R14*U14 -> 2.9482712
B15: Somme 228Th | G15: =G14 -> 1324.9667 | H15: =H14 -> 1.15 | I15: 0.005 | J15: =J9+J10 -> 0.215 | K15: =K9+K10 -> 1982 | L15: =L9+L10 -> 169 | M15: =M9+M10 -> 158 | N15: =N9+N10 -> 1818.5 | O15: ± | P15: =SQRT((K15+(L15+M15)/2)) -> 46.319542 | Q15: =N15/G15 -> 1.3724874 | R15: =(Q15/H15/J15) -> 5.5510105 | S15: ± | T15: =P15/N15*R15 -> 0.1413914 | U15: =R15/60*1000 -> 92.516842 | V15: ± | W15: =T15/R15*U15 -> 2.3565234 | X15: 3225
B16: Somme 228Ra | G16: =G10 -> 1324.9667 | H16: =H10 -> 1.15 | I16: 0.005 | J16: =J11+J12+J13 -> 0.079 | K16: =K11+K12+K13 -> 746 | L16: =L11+L12+L13 -> 137 | M16: =M11+M12+M13 -> 137 | N16: =N11+N12+N13 -> 609 | O16: ± | P16: =SQRT((K16+(L16+M16)/2)) -> 29.715316 | Q16: =N16/G16 -> 0.4596342 | R16: =(Q16/H16/J16) -> 5.0592648 | S16: ± | T16: =P16/N16*R16 -> 0.24685985 | U16: =R16/60*1000 -> 84.32108 | V16: ± | W16: =T16/R16*U16 -> 4.1143309 | X16: 3225
A18: NOI_4 | B18: 79 498,000
A20: Isotope | B20: Energie(Kev) | C20: Somme pic | D20: Somme bkg gauche | E20: Somme bkg droit | F20: Somme-bkg | G20: Sigma
A21: 210Pb | B21: 46.4991 | C21: 4 202 | D21: 330 | E21: 251 | F21: 3 940 | G21: 64.82
A22: 241Am | B22: 59.7484 | C22: 294 | D22: 197 | E22: 194 | F22: 120 | G22: 17.15
A23: 214Pb | B23: 295.178 | C23: 1 466 | D23: 91 | E23: 58 | F23: 1 397 | G23: 38.29
A24: 214Pb | B24: 351.881 | C24: 2 570 | D24: 88 | E24: 79 | F24: 2 495 | G24: 50.7
A25: 214Bi | B25: 609.176 | C25: 823 | D25: 42 | E25: 51 | F25: 779 | G25: 28.69
A26: 137Cs | B26: 661.617 | C26: 3 933 | D26: 63 | E26: 46 | F26: 3 881 | G26: 62.71
A27: 40K | B27: 1460.19 | C27: 1 047 | D27: 22 | E27: 23 | F27: 1 025 | G27: 32.36
A28: 214Bi | B28: 1121.17 | C28: 142 | D28: 39 | E28: 43 | F28: 102 | G28: 11.92
A29: 228Ac | B29: 1775.39 | C29: 5 | D29: 22 | E29: 9 | F29: -9 | G29: 2.24
A30: 234Th | B30: 63.3618 | C30: 2 546 | D30: 280 | E30: 279 | F30: 2 294 | G30: 50.46
A31: 226Ra | B31: 185.848 | C31: 1 978 | D31: 164 | E31: 127 | F31: 1 850 | G31: 44.47
A32: 212Pb | B32: 238.567 | C32: 1 724 | D32: 119 | E32: 119 | F32: 1 612 | G32: 41.52
A33: 208Tl | B33: 582.956 | C33: 258 | D33: 50 | E33: 39 | F33: 216 | G33: 16.06
A34: 228Ac | B34: 338.076 | C34: 319 | D34: 70 | E34: 69 | F34: 255 | G34: 17.86
A35: 228Ac | B35: 910.852 | C35: 238 | D35: 40 | E35: 40 | F35: 199 | G35: 15.43
A36: 228Ac | B36: 968.852 | C36: 189 | D36: 27 | E36: 28 | F36: 162 | G36: 13.75
A37: 235U | B37: 143.691 | C37: 488 | D37: 148 | E37: 132 | F37: 324 | G37: 22.09

Sheet 5
A1: NOM | B1: Nucleide | C1: E kev | D1: Canaux | E1: %emis | F1: Rendement | G1: temps | H1: poids | I1: bdf | J1: eff | K1: pic1 | L1: bdfg | M1: bdfd | O1: pic net | Q1: cpm | S1: dpm/g | V1: Bq/k | X1: Data Certif
A2: RGU | B2: 210Pb | C2: 46.5 | D2: 9 | E2: 0.04 | F2: 0.535 | G2: =85125/60 -> 1418.75 | H2: =2.92-1.8 -> 1.12 | I2: 0 | J2: 0.0214 | K2: 4220 | L2: 321 | M2: 280 | N2: =K2-(L2+M2)/2 -> 3919.5 | O2: ± | P2: =SQRT((K2+(L2+M2)/2)) -> 67.234664 | Q2: =N2/G2 -> 2.7626432 | R2: =(Q2/H2/J2) -> 115.26382 | S2: ± | T2: =P2/N2*R2 -> 1.9772226 | U2: =R2/60*1000 -> 1921.0636 | V2: ± | W2: =T2/R2*U2 -> 32.95371 | X2: 4940
A3: IAEA447 | B3: 241Am | C3: 59.5 | D3: 8 | E3: 0.363 | F3: 0.71625344 | G3: =G2 -> 1418.75 | H3: =H2 -> 1.12 | I3: 0 | J3: 0.26 | K3: 304 | L3: 235 | M3: 244 | N3: =K3-(L3+M3)/2 -> 64.5 | O3: ± | P3: =SQRT((K3+(L3+M3)/2)) -> 23.313086 | Q3: =N3/G3 -> 0.045462555 | R3: =Q3/H3/J3 -> 0.15612141 | S3: ± | T3: =P3/N3*R3 -> 0.056429023 | U3: =R3/60*1000 -> 2.6020235 | V3: ± | W3: =T3/R3*U3 -> 0.94048371 | X3: 2.15
A4: RGU1 | B4: 214Bi | C4: 295 | D4: 11 | E4: 0.192 | F4: 0.421875 | G4: =G2 -> 1418.75 | H4: =H2 -> 1.12 | J4: 0.081 | K4: 1572 | L4: 86 | M4: 65 | N4: =K4-(L4+M4)/2 -> 1496.5 | O4: ± | P4: =SQRT((K4+(L4+M4)/2)) -> 40.589407 | Q4: =N4/G4 -> 1.0548018 | R4: =(Q4/H4/J4) -> 11.627004 | S4: ± | T4: =P4/N4*R4 -> 0.31535796 | U4: =R4/60*1000 -> 193.78339 | V4: ± | W4: =T4/R4*U4 -> 5.255966 | X4: 4940
A5: RGU1 | B5: 214Bi | C5: 352 | D5: 12 | E5: 0.371 | F5: 0.36927224 | G5: =G2 -> 1418.75 | H5: =H2 -> 1.12 | I5: 0.002 | J5: 0.137 | K5: 2577 | L5: 104 | M5: 70 | N5: =K5-(L5+M5)/2 -> 2490 | O5: ± | P5: =SQRT((K5+(L5+M5)/2)) -> 51.613952 | Q5: =N5/G5 -> 1.7550661 | R5: =(Q5/H5/J5) -> 11.438126 | S5: ± | T5: =P5/N5*R5 -> 0.23709514 | U5: =R5/60*1000 -> 190.63544 | V5: ± | W5: =T5/R5*U5 -> 3.9515856 | X5: 4940
A6: RGU1 | B6: 214Bi | C6: 609 | D6: 16 | E6: 0.461 | F6: 0.09978308 | G6: =G2 -> 1418.75 | H6: =H2 -> 1.12 | I6: 0.002 | J6: 0.046 | K6: 905 | L6: 44 | M6: 55 | N6: =K6-(L6+M6)/2 -> 855.5 | O6: ± | P6: =SQRT((K6+(L6+M6)/2)) -> 30.894983 | Q6: =N6/G6 -> 0.60299559 | R6: =(Q6/H6/J6) -> 11.704107 | S6: ± | T6: =P6/N6*R6 -> 0.42267468 | U6: =R6/60*1000 -> 195.06845 | V6: ± | W6: =T6/R6*U6 -> 7.0445781 | X6: 4940
A7: IAEA447 | B7: 137Cs | C7: 661 | D7: 20 | E7: 0.8462 | F7: 0.29189317 | G7: =G2 -> 1418.75 | H7: =H2 -> 1.12 | I7: 0.001 | J7: 0.247 | K7: 3973 | L7: 67 | M7: 53 | N7: =K7-(L7+M7)/2 -> 3913 | O7: ± | P7: =SQRT((K7+(L7+M7)/2)) -> 63.505905 | Q7: =N7/G7 -> 2.7580617 | R7: =Q7/H7/J7 -> 9.9698586 | S7: ± | T7: =P7/N7*R7 -> 0.16180549 | U7: =R7/60*1000 -> 166.16431 | V7: ± | W7: =T7/R7*U7 -> 2.6967582 | X7: 335
A8: RGU | B8: 40K | C8: 1460 | D8: 20 | E8: 0.107 | F8: 0.14485981 | G8: =G2 -> 1418.75 | H8: =H2 -> 1.12 | I8: 0.004 | J8: 0.0155 | K8: 1052 | L8: 26 | M8: 22 | N8: =K8-(L8+M8)/2 -> 1028 | O8: ± | P8: =SQRT((K8+(L8+M8)/2)) -> 32.802439 | Q8: =N8/G8 -> 0.7245815 | R8: =Q8/H8/J8 -> 41.738566 | S8: ± | T8: =P8/N8*R8 -> 1.3318354 | U8: =R8/60*1000 -> 695.64276 | V8: ± | W8: =T8/R8*U8 -> 22.197256 | X8: 550
A9: RGTh | B9: 212Pb | C9: 238 | D9: 11 | E9: 0.431 | G9: =G3 -> 1418.75 | H9: =H2 -> 1.12 | J9: 0.19 | K9: 1800 | L9: 140 | M9: 130 | N9: =K9-(L9+M9)/2 -> 1665 | P9: =SQRT((K9+(L9+M9)/2)) -> 43.988635 | Q9: =N9/G9 -> 1.1735683 | R9: =Q9/H9/J9 -> 5.5148885 | S9: ± | T9: =P9/N9*R9 -> 0.14570115 | U9: =R9/60*1000 -> 91.914809 | V9: ± | W9: =T9/R9*U9 -> 2.4283525
A10: RGTh | B10: 208Tl | C10: 583 | D10: 13 | G10: =G4 -> 1418.75 | H10: =H2 -> 1.12 | J10: 0.025 | K10: 268 | L10: 49 | M10: 48 | N10: =K10-(L10+M10)/2 -> 219.5 | P10: =SQRT((K10+(L10+M10)/2)) -> 17.790447 | Q10: =N10/G10 -> 0.15471366 | R10: =Q10/H10/J10 -> 5.5254877 | S10: ± | T10: =P10/N10*R10 -> 0.44784007 | U10: =R10/60*1000 -> 92.091462 | V10: ± | W10: =T10/R10*U10 -> 7.4640012
A11: RGTh | B11: 228Ac | C11: 338 | D11: 16 | E11: 0.12 | G11: =G3 -> 1418.75 | H11: =H2 -> 1.12 | J11: 0.031 | K11: 318 | L11: 72 | M11: 64 | N11: =K11-(L11+M11)/2 -> 250 | P11: =SQRT((K11+(L11+M11)/2)) -> 19.646883 | Q11: =N11/G11 -> 0.17621145 | R11: =Q11/H11/J11 -> 5.0752147 | S11: ± | T11: =P11/N11*R11 -> 0.39884859 | U11: =R11/60*1000 -> 84.586911 | V11: ± | W11: =T11/R11*U11 -> 6.6474765
A12: RGTh | B12: 228Ac | C12: 911 | D12: 20 | E12: 0.29 | G12: =G2 -> 1418.75 | H12: =H2 -> 1.12 | J12: 0.03 | K12: 315 | L12: 47 | M12: 43 | N12: =K12-(L12+M12)/2 -> 270 | P12: =SQRT((K12+(L12+M12)/2)) -> 18.973666 | Q12: =N12/G12 -> 0.19030837 | R12: =Q12/H12/J12 -> 5.6639396 | S12: ± | T12: =P12/N12*R12 -> 0.3980211 | U12: =R12/60*1000 -> 94.398993 | V12: ± | W12: =T12/R12*U12 -> 6.633685
A13: RGTh | B13: 228Ac | C13: 968 | D13: 14 | E13: 0.18 | G13: =G3 -> 1418.75 | H13: =H2 -> 1.12 | J13: 0.018 | K13: 174 | L13: 43 | M13: 44 | N13: =K13-(L13+M13)/2 -> 130.5 | P13: =SQRT((K13+(L13+M13)/2)) -> 14.747881 | Q13: =N13/G13 -> 0.091982379 | R13: =Q13/H13/J13 -> 4.562618 | S13: ± | T13: =P13/N13*R13 -> 0.51562412 | U13: =R13/60*1000 -> 76.043633 | V13: ± | W13: =T13/R13*U13 -> 8.5937354
B14: Somme 226Ra | G14: =G2 -> 1418.75 | H14: =H2 -> 1.12 | I14: 0.005 | J14: =J4+J5+J6 -> 0.264 | K14: =K4+K5+K6 -> 5054 | L14: =L4+L5+L6 -> 234 | M14: =M4+M5+M6 -> 190 | N14: =N4+N5+N6 -> 4842 | O14: ± | P14: =SQRT((K14+(L14+M14)/2)) -> 72.56721 | Q14: =N14/G14 -> 3.4128634 | R14: =(Q14/H14/J14) -> 11.542422 | S14: ± | T14: =P14/N14*R14 -> 0.17298666 | U14: =R14/60*1000 -> 192.37371 | V14: ± | W14: =T14/R14*U14 -> 2.8831109
B15: Somme 228Th | G15: =G14 -> 1418.75 | H15: =H14 -> 1.12 | I15: 0.005 | J15: =J9+J10 -> 0.215 | K15: =K9+K10 -> 2068 | L15: =L9+L10 -> 189 | M15: =M9+M10 -> 178 | N15: =N9+N10 -> 1884.5 | O15: ± | P15: =SQRT((K15+(L15+M15)/2)) -> 47.449974 | Q15: =N15/G15 -> 1.3282819 | R15: =(Q15/H15/J15) -> 5.516121 | S15: ± | T15: =P15/N15*R15 -> 0.13889084 | U15: =R15/60*1000 -> 91.93535 | V15: ± | W15: =T15/R15*U15 -> 2.3148474 | X15: 3225
B16: Somme 228Ra | G16: =G10 -> 1418.75 | H16: =H10 -> 1.12 | I16: 0.005 | J16: =J11+J12+J13 -> 0.079 | K16: =K11+K12+K13 -> 807 | L16: =L11+L12+L13 -> 162 | M16: =M11+M12+M13 -> 151 | N16: =N11+N12+N13 -> 650.5 | O16: ± | P16: =SQRT((K16+(L16+M16)/2)) -> 31.040296 | Q16: =N16/G16 -> 0.4585022 | R16: =(Q16/H16/J16) -> 5.1819869 | S16: ± | T16: =P16/N16*R16 -> 0.24727196 | U16: =R16/60*1000 -> 86.366449 | V16: ± | W16: =T16/R16*U16 -> 4.1211993 | X16: 3225
A18: NOI_5 | B18: 85 125,000
A20: Isotope | B20: Energie(Kev) | C20: Somme pic | D20: Somme bkg gauche | E20: Somme bkg droit | F20: Somme-bkg | G20: Sigma
A21: 210Pb | B21: 46.4991 | C21: 4 220 | D21: 321 | E21: 280 | F21: 3 949 | G21: 64.96
A22: 241Am | B22: 59.7484 | C22: 304 | D22: 235 | E22: 244 | F22: 91 | G22: 17.44
A23: 214Pb | B23: 295.178 | C23: 1 572 | D23: 86 | E23: 65 | F23: 1 502 | G23: 39.65
A24: 214Pb | B24: 351.881 | C24: 2 577 | D24: 104 | E24: 70 | F24: 2 499 | G24: 50.76
A25: 214Bi | B25: 609.176 | C25: 905 | D25: 44 | E25: 55 | F25: 858 | G25: 30.08
A26: 137Cs | B26: 661.617 | C26: 3 973 | D26: 67 | E26: 53 | F26: 3 916 | G26: 63.03
A27: 40K | B27: 1460.19 | C27: 1 052 | D27: 26 | E27: 22 | F27: 1 028 | G27: 32.43
A28: 214Bi | B28: 1121.17 | C28: 174 | D28: 30 | E28: 36 | F28: 142 | G28: 13.19
A29: 228Ac | B29: 1775.39 | C29: 12 | D29: 20 | E29: 10 | F29: -2 | G29: 3.46
A30: 234Th | B30: 63.3618 | C30: 2 444 | D30: 281 | E30: 280 | F30: 2 191 | G30: 49.44
A31: 226Ra | B31: 185.848 | C31: 2 006 | D31: 123 | E31: 151 | F31: 1 884 | G31: 44.79
A32: 212Pb | B32: 238.567 | C32: 1 800 | D32: 140 | E32: 130 | F32: 1 674 | G32: 42.43
A33: 208Tl | B33: 582.956 | C33: 268 | D33: 49 | E33: 48 | F33: 222 | G33: 16.37
A34: 228Ac | B34: 338.076 | C34: 318 | D34: 72 | E34: 64 | F34: 256 | G34: 17.83
A35: 228Ac | B35: 910.852 | C35: 315 | D35: 47 | E35: 43 | F35: 272 | G35: 17.75
A36: 228Ac | B36: 968.852 | C36: 174 | D36: 43 | E36: 44 | F36: 132 | G36: 13.19
A37: 235U | B37: 143.691 | C37: 526 | D37: 144 | E37: 135 | F37: 363 | G37: 22.93

Sheet 6
A1: NOM | B1: Nucleide | C1: E kev | D1: Canaux | E1: %emis | F1: Rendement | G1: temps | H1: poids | I1: bdf | J1: eff | K1: pic1 | L1: bdfg | M1: bdfd | O1: pic net | Q1: cpm | S1: dpm/g | V1: Bq/k | X1: Data Certif
A2: RGU | B2: 210Pb | C2: 46.5 | D2: 9 | E2: 0.04 | F2: 0.535 | G2: =83657/60 -> 1394.2833 | H2: =2.84-1.77 -> 1.07 | I2: 0 | J2: 0.0214 | K2: 3467 | L2: 284 | M2: 234 | N2: =K2-(L2+M2)/2 -> 3208 | O2: ± | P2: =SQRT((K2+(L2+M2)/2)) -> 61.04097 | Q2: =N2/G2 -> 2.3008236 | R2: =(Q2/H2/J2) -> 100.48142 | S2: ± | T2: =P2/N2*R2 -> 1.9119337 | U2: =R2/60*1000 -> 1674.6904 | V2: ± | W2: =T2/R2*U2 -> 31.865562 | X2: 4940
A3: IAEA447 | B3: 241Am | C3: 59.5 | D3: 8 | E3: 0.363 | F3: 0.71625344 | G3: =G2 -> 1394.2833 | H3: =H2 -> 1.07 | I3: 0 | J3: 0.26 | K3: 283 | L3: 234 | M3: 233 | N3: =K3-(L3+M3)/2 -> 49.5 | O3: ± | P3: =SQRT((K3+(L3+M3)/2)) -> 22.726636 | Q3: =N3/G3 -> 0.03550211 | R3: =Q3/H3/J3 -> 0.12761362 | S3: ± | T3: =P3/N3*R3 -> 0.058590473 | U3: =R3/60*1000 -> 2.1268937 | V3: ± | W3: =T3/R3*U3 -> 0.97650788 | X3: 2.15
A4: RGU1 | B4: 214Bi | C4: 295 | D4: 11 | E4: 0.192 | F4: 0.421875 | G4: =G2 -> 1394.2833 | H4: =H2 -> 1.07 | J4: 0.081 | K4: 1418 | L4: 81 | M4: 66 | N4: =K4-(L4+M4)/2 -> 1344.5 | O4: ± | P4: =SQRT((K4+(L4+M4)/2)) -> 38.619943 | Q4: =N4/G4 -> 0.96429468 | R4: =(Q4/H4/J4) -> 11.126049 | S4: ± | T4: =P4/N4*R4 -> 0.31958898 | U4: =R4/60*1000 -> 185.43415 | V4: ± | W4: =T4/R4*U4 -> 5.326483 | X4: 4940
A5: RGU1 | B5: 214Bi | C5: 352 | D5: 12 | E5: 0.371 | F5: 0.36927224 | G5: =G2 -> 1394.2833 | H5: =H2 -> 1.07 | I5: 0.002 | J5: 0.137 | K5: 2369 | L5: 93 | M5: 76 | N5: =K5-(L5+M5)/2 -> 2284.5 | O5: ± | P5: =SQRT((K5+(L5+M5)/2)) -> 49.532817 | Q5: =N5/G5 -> 1.6384762 | R5: =(Q5/H5/J5) -> 11.177271 | S5: ± | T5: =P5/N5*R5 -> 0.242347 | U5: =R5/60*1000 -> 186.28785 | V5: ± | W5: =T5/R5*U5 -> 4.0391167 | X5: 4940
A6: RGU1 | B6: 214Bi | C6: 609 | D6: 16 | E6: 0.461 | F6: 0.09978308 | G6: =G2 -> 1394.2833 | H6: =H2 -> 1.07 | I6: 0.002 | J6: 0.046 | K6: 823 | L6: 48 | M6: 46 | N6: =K6-(L6+M6)/2 -> 776 | O6: ± | P6: =SQRT((K6+(L6+M6)/2)) -> 29.495762 | Q6: =N6/G6 -> 0.55655833 | R6: =(Q6/H6/J6) -> 11.307565 | S6: ± | T6: =P6/N6*R6 -> 0.42980056 | U6: =R6/60*1000 -> 188.45941 | V6: ± | W6: =T6/R6*U6 -> 7.1633427 | X6: 4940
A7: IAEA447 | B7: 137Cs | C7: 661 | D7: 20 | E7: 0.8462 | F7: 0.29189317 | G7: =G2 -> 1394.2833 | H7: =H2 -> 1.07 | I7: 0.001 | J7: 0.247 | K7: 3764 | L7: 73 | M7: 35 | N7: =K7-(L7+M7)/2 -> 3710 | O7: ± | P7: =SQRT((K7+(L7+M7)/2)) -> 61.789967 | Q7: =N7/G7 -> 2.6608652 | R7: =Q7/H7/J7 -> 10.067975 | S7: ± | T7: =P7/N7*R7 -> 0.1676819 | U7: =R7/60*1000 -> 167.79959 | V7: ± | W7: =T7/R7*U7 -> 2.7946984 | X7: 335
A8: RGU | B8: 40K | C8: 1460 | D8: 20 | E8: 0.107 | F8: 0.14485981 | G8: =G2 -> 1394.2833 | H8: =H2 -> 1.07 | I8: 0.004 | J8: 0.0155 | K8: 1074 | L8: 29 | M8: 30 | N8: =K8-(L8+M8)/2 -> 1044.5 | O8: ± | P8: =SQRT((K8+(L8+M8)/2)) -> 33.21897 | Q8: =N8/G8 -> 0.74913038 | R8: =Q8/H8/J8 -> 45.169151 | S8: ± | T8: =P8/N8*R8 -> 1.4365464 | U8: =R8/60*1000 -> 752.81919 | V8: ± | W8: =T8/R8*U8 -> 23.94244 | X8: 550
A9: RGTh | B9: 212Pb | C9: 238 | D9: 11 | E9: 0.431 | G9: =G3 -> 1394.2833 | H9: =H2 -> 1.07 | J9: 0.19 | K9: 1590 | L9: 121 | M9: 109 | N9: =K9-(L9+M9)/2 -> 1475 | P9: =SQRT((K9+(L9+M9)/2)) -> 41.291646 | Q9: =N9/G9 -> 1.0578912 | R9: =Q9/H9/J9 -> 5.2035964 | S9: ± | T9: =P9/N9*R9 -> 0.14567123 | U9: =R9/60*1000 -> 86.726607 | V9: ± | W9: =T9/R9*U9 -> 2.4278538
A10: RGTh | B10: 208Tl | C10: 583 | D10: 13 | G10: =G4 -> 1394.2833 | H10: =H2 -> 1.07 | J10: 0.025 | K10: 213 | L10: 46 | M10: 44 | N10: =K10-(L10+M10)/2 -> 168 | P10: =SQRT((K10+(L10+M10)/2)) -> 16.062378 | Q10: =N10/G10 -> 0.12049201 | R10: =Q10/H10/J10 -> 4.5043742 | S10: ± | T10: =P10/N10*R10 -> 0.43066049 | U10: =R10/60*1000 -> 75.072903 | V10: ± | W10: =T10/R10*U10 -> 7.1776748
A11: RGTh | B11: 228Ac | C11: 338 | D11: 16 | E11: 0.12 | G11: =G3 -> 1394.2833 | H11: =H2 -> 1.07 | J11: 0.031 | K11: 314 | L11: 69 | M11: 58 | N11: =K11-(L11+M11)/2 -> 250.5 | P11: =SQRT((K11+(L11+M11)/2)) -> 19.429359 | Q11: =N11/G11 -> 0.17966219 | R11: =Q11/H11/J11 -> 5.4164062 | S11: ± | T11: =P11/N11*R11 -> 0.42010899 | U11: =R11/60*1000 -> 90.273436 | V11: ± | W11: =T11/R11*U11 -> 7.0018164
A12: RGTh | B12: 228Ac | C12: 911 | D12: 20 | E12: 0.29 | G12: =G2 -> 1394.2833 | H12: =H2 -> 1.07 | J12: 0.03 | K12: 299 | L12: 38 | M12: 47 | N12: =K12-(L12+M12)/2 -> 256.5 | P12: =SQRT((K12+(L12+M12)/2)) -> 18.479719 | Q12: =N12/G12 -> 0.18396548 | R12: =Q12/H12/J12 -> 5.7310118 | S12: ± | T12: =P12/N12*R12 -> 0.41289468 | U12: =R12/60*1000 -> 95.516863 | V12: ± | W12: =T12/R12*U12 -> 6.881578
A13: RGTh | B13: 228Ac | C13: 968 | D13: 14 | E13: 0.18 | G13: =G3 -> 1394.2833 | H13: =H2 -> 1.07 | J13: 0.018 | K13: 161 | L13: 26 | M13: 24 | N13: =K13-(L13+M13)/2 -> 136 | P13: =SQRT((K13+(L13+M13)/2)) -> 13.638182 | Q13: =N13/G13 -> 0.09754115 | R13: =Q13/H13/J13 -> 5.0644419 | S13: ± | T13: =P13/N13*R13 -> 0.50786602 | U13: =R13/60*1000 -> 84.407364 | V13: ± | W13: =T13/R13*U13 -> 8.4644336
B14: Somme 226Ra | G14: =G2 -> 1394.2833 | H14: =H2 -> 1.07 | I14: 0.005 | J14: =J4+J5+J6 -> 0.264 | K14: =K4+K5+K6 -> 4610 | L14: =L4+L5+L6 -> 222 | M14: =M4+M5+M6 -> 188 | N14: =N4+N5+N6 -> 4405 | O14: ± | P14: =SQRT((K14+(L14+M14)/2)) -> 69.390201 | Q14: =N14/G14 -> 3.1593292 | R14: =(Q14/H14/J14) -> 11.184258 | S14: ± | T14: =P14/N14*R14 -> 0.17618114 | U14: =R14/60*1000 -> 186.4043 | V14: ± | W14: =T14/R14*U14 -> 2.9363523
B15: Somme 228Th | G15: =G14 -> 1394.2833 | H15: =H14 -> 1.07 | I15: 0.005 | J15: =J9+J10 -> 0.215 | K15: =K9+K10 -> 1803 | L15: =L9+L10 -> 167 | M15: =M9+M10 -> 153 | N15: =N9+N10 -> 1643 | O15: ± | P15: =SQRT((K15+(L15+M15)/2)) -> 44.305756 | Q15: =N15/G15 -> 1.1783832 | R15: =(Q15/H15/J15) -> 5.1222915 | S15: ± | T15: =P15/N15*R15 -> 0.13812964 | U15: =R15/60*1000 -> 85.371525 | V15: ± | W15: =T15/R15*U15 -> 2.3021606 | X15: 3225
B16: Somme 228Ra | G16: =G10 -> 1394.2833 | H16: =H10 -> 1.07 | I16: 0.005 | J16: =J11+J12+J13 -> 0.079 | K16: =K11+K12+K13 -> 774 | L16: =L11+L12+L13 -> 133 | M16: =M11+M12+M13 -> 129 | N16: =N11+N12+N13 -> 643 | O16: ± | P16: =SQRT((K16+(L16+M16)/2)) -> 30.083218 | Q16: =N16/G16 -> 0.46116882 | R16: =(Q16/H16/J16) -> 5.4556822 | S16: ± | T16: =P16/N16*R16 -> 0.25524802 | U16: =R16/60*1000 -> 90.928037 | V16: ± | W16: =T16/R16*U16 -> 4.2541337 | X16: 3225
A18: NOI_6 | B18: 83 657,000
A20: Isotope | B20: Energie(Kev) | C20: Somme pic | D20: Somme bkg gauche | E20: Somme bkg droit | F20: Somme-bkg | G20: Sigma
A21: 210Pb | B21: 46.4991 | C21: 3 467 | D21: 284 | E21: 234 | F21: 3 233 | G21: 58.88
A22: 241Am | B22: 59.5631 | C22: 283 | D22: 234 | E22: 233 | F22: 75 | G22: 16.82
A23: 214Pb | B23: 295.178 | C23: 1 418 | D23: 81 | E23: 66 | F23: 1 350 | G23: 37.66
A24: 214Pb | B24: 351.881 | C24: 2 369 | D24: 93 | E24: 76 | F24: 2 293 | G24: 48.67
A25: 214Bi | B25: 609.176 | C25: 823 | D25: 48 | E25: 46 | F25: 778 | G25: 28.69
A26: 137Cs | B26: 661.617 | C26: 3 764 | D26: 73 | E26: 35 | F26: 3 712 | G26: 61.35
A27: 40K | B27: 1460.19 | C27: 1 074 | D27: 29 | E27: 30 | F27: 1 045 | G27: 32.77
A28: 214Bi | B28: 1121.17 | C28: 136 | D28: 30 | E28: 31 | F28: 106 | G28: 11.66
A29: 228Ac | B29: 1775.39 | C29: 9 | D29: 18 | E29: 13 | F29: -5 | G29: 3
A30: 234Th | B30: 63.3618 | C30: 2 376 | D30: 248 | E30: 254 | F30: 2 150 | G30: 48.74
A31: 226Ra | B31: 185.848 | C31: 1 947 | D31: 134 | E31: 122 | F31: 1 834 | G31: 44.12
A32: 212Pb | B32: 238.567 | C32: 1 590 | D32: 121 | E32: 109 | F32: 1 482 | G32: 39.87
A33: 208Tl | B33: 582.956 | C33: 213 | D33: 46 | E33: 44 | F33: 170 | G33: 14.59
A34: 228Ac | B34: 338.076 | C34: 314 | D34: 69 | E34: 58 | F34: 256 | G34: 17.72
A35: 228Ac | B35: 910.852 | C35: 299 | D35: 38 | E35: 47 | F35: 258 | G35: 17.29
A36: 228Ac | B36: 968.852 | C36: 161 | D36: 26 | E36: 24 | F36: 137 | G36: 12.69
A37: 235U | B37: 143.691 | C37: 495 | D37: 117 | E37: 116 | F37: 359 | G37: 22.25

Sheet 7
A1: NOM | B1: Nucleide | C1: E kev | D1: Canaux | E1: %emis | F1: Rendement | G1: temps | H1: poids | I1: bdf | J1: eff | K1: pic1 | L1: bdfg | M1: bdfd | O1: pic net | Q1: cpm | S1: dpm/g | V1: Bq/k | X1: Data Certif
A2: RGU | B2: 210Pb | C2: 46.5 | D2: 9 | E2: 0.04 | F2: 0.535 | G2: =81447/60 -> 1357.45 | H2: =2.83-1.77 -> 1.06 | I2: 0 | J2: 0.0214 | K2: 2202 | L2: 243 | M2: 208 | N2: =K2-(L2+M2)/2 -> 1976.5 | O2: ± | P2: =SQRT((K2+(L2+M2)/2)) -> 49.269666 | Q2: =N2/G2 -> 1.4560389 | R2: =(Q2/H2/J2) -> 64.187925 | S2: ± | T2: =P2/N2*R2 -> 1.6000595 | U2: =R2/60*1000 -> 1069.7988 | V2: ± | W2: =T2/R2*U2 -> 26.667659 | X2: 4940
A3: IAEA447 | B3: 241Am | C3: 59.5 | D3: 8 | E3: 0.363 | F3: 0.71625344 | G3: =G2 -> 1357.45 | H3: =H2 -> 1.06 | I3: 0 | J3: 0.26 | K3: 261 | L3: 176 | M3: 185 | N3: =K3-(L3+M3)/2 -> 80.5 | O3: ± | P3: =SQRT((K3+(L3+M3)/2)) -> 21.011901 | Q3: =N3/G3 -> 0.059302368 | R3: =Q3/H3/J3 -> 0.2151755 | S3: ± | T3: =P3/N3*R3 -> 0.056164552 | U3: =R3/60*1000 -> 3.5862584 | V3: ± | W3: =T3/R3*U3 -> 0.93607587 | X3: 2.15
A4: RGU1 | B4: 214Bi | C4: 295 | D4: 11 | E4: 0.192 | F4: 0.421875 | G4: =G2 -> 1357.45 | H4: =H2 -> 1.06 | J4: 0.081 | K4: 1335 | L4: 68 | M4: 64 | N4: =K4-(L4+M4)/2 -> 1269 | O4: ± | P4: =SQRT((K4+(L4+M4)/2)) -> 37.429935 | Q4: =N4/G4 -> 0.93484106 | R4: =(Q4/H4/J4) -> 10.88797 | S4: ± | T4: =P4/N4*R4 -> 0.32114735 | U4: =R4/60*1000 -> 181.46616 | V4: ± | W4: =T4/R4*U4 -> 5.3524558 | X4: 4940
A5: RGU1 | B5: 214Bi | C5: 352 | D5: 12 | E5: 0.371 | F5: 0.36927224 | G5: =G2 -> 1357.45 | H5: =H2 -> 1.06 | I5: 0.002 | J5: 0.137 | K5: 2099 | L5: 64 | M5: 58 | N5: =K5-(L5+M5)/2 -> 2038 | O5: ± | P5: =SQRT((K5+(L5+M5)/2)) -> 46.4758 | Q5: =N5/G5 -> 1.5013444 | R5: =(Q5/H5/J5) -> 10.338414 | S5: ± | T5: =P5/N5*R5 -> 0.23576352 | U5: =R5/60*1000 -> 172.30689 | V5: ± | W5: =T5/R5*U5 -> 3.9293919 | X5: 4940
A6: RGU1 | B6: 214Bi | C6: 609 | D6: 16 | E6: 0.461 | F6: 0.09978308 | G6: =G2 -> 1357.45 | H6: =H2 -> 1.06 | I6: 0.002 | J6: 0.046 | K6: 691 | L6: 49 | M6: 41 | N6: =K6-(L6+M6)/2 -> 646 | O6: ± | P6: =SQRT((K6+(L6+M6)/2)) -> 27.12932 | Q6: =N6/G6 -> 0.4758923 | R6: =(Q6/H6/J6) -> 9.7598913 | S6: ± | T6: =P6/N6*R6 -> 0.40987494 | U6: =R6/60*1000 -> 162.66485 | V6: ± | W6: =T6/R6*U6 -> 6.831249 | X6: 4940
A7: IAEA447 | B7: 137Cs | C7: 661 | D7: 20 | E7: 0.8462 | F7: 0.29189317 | G7: =G2 -> 1357.45 | H7: =H2 -> 1.06 | I7: 0.001 | J7: 0.247 | K7: 3246 | L7: 51 | M7: 34 | N7: =K7-(L7+M7)/2 -> 3203.5 | O7: ± | P7: =SQRT((K7+(L7+M7)/2)) -> 57.345444 | Q7: =N7/G7 -> 2.3599396 | R7: =Q7/H7/J7 -> 9.0135956 | S7: ± | T7: =P7/N7*R7 -> 0.16135122 | U7: =R7/60*1000 -> 150.22659 | V7: ± | W7: =T7/R7*U7 -> 2.6891871 | X7: 335
A8: RGU | B8: 40K | C8: 1460 | D8: 20 | E8: 0.107 | F8: 0.14485981 | G8: =G2 -> 1357.45 | H8: =H2 -> 1.06 | I8: 0.004 | J8: 0.0155 | K8: 1139 | L8: 30 | M8: 26 | N8: =K8-(L8+M8)/2 -> 1111 | O8: ± | P8: =SQRT((K8+(L8+M8)/2)) -> 34.161382 | Q8: =N8/G8 -> 0.81844635 | R8: =Q8/H8/J8 -> 49.814142 | S8: ± | T8: =P8/N8*R8 -> 1.5317011 | U8: =R8/60*1000 -> 830.2357 | V8: ± | W8: =T8/R8*U8 -> 25.528352 | X8: 550
A9: RGTh | B9: 212Pb | C9: 238 | D9: 11 | E9: 0.431 | G9: =G3 -> 1357.45 | H9: =H2 -> 1.06 | J9: 0.19 | K9: 1557 | L9: 117 | M9: 96 | N9: =K9-(L9+M9)/2 -> 1450.5 | P9: =SQRT((K9+(L9+M9)/2)) -> 40.786027 | Q9: =N9/G9 -> 1.0685476 | R9: =Q9/H9/J9 -> 5.305599 | S9: ± | T9: =P9/N9*R9 -> 0.14918601 | U9: =R9/60*1000 -> 88.42665 | V9: ± | W9: =T9/R9*U9 -> 2.4864335
A10: RGTh | B10: 208Tl | C10: 583 | D10: 13 | G10: =G4 -> 1357.45 | H10: =H2 -> 1.06 | J10: 0.025 | K10: 230 | L10: 40 | M10: 49 | N10: =K10-(L10+M10)/2 -> 185.5 | P10: =SQRT((K10+(L10+M10)/2)) -> 16.568042 | Q10: =N10/G10 -> 0.13665328 | R10: =Q10/H10/J10 -> 5.1567277 | S10: ± | T10: =P10/N10*R10 -> 0.46057616 | U10: =R10/60*1000 -> 85.945461 | V10: ± | W10: =T10/R10*U10 -> 7.6762694
A11: RGTh | B11: 228Ac | C11: 338 | D11: 16 | E11: 0.12 | G11: =G3 -> 1357.45 | H11: =H2 -> 1.06 | J11: 0.031 | K11: 267 | L11: 50 | M11: 53 | N11: =K11-(L11+M11)/2 -> 215.5 | P11: =SQRT((K11+(L11+M11)/2)) -> 17.846568 | Q11: =N11/G11 -> 0.15875355 | R11: =Q11/H11/J11 -> 4.8312095 | S11: ± | T11: =P11/N11*R11 -> 0.40009518 | U11: =R11/60*1000 -> 80.520159 | V11: ± | W11: =T11/R11*U11 -> 6.668253
A12: RGTh | B12: 228Ac | C12: 911 | D12: 20 | E12: 0.29 | G12: =G2 -> 1357.45 | H12: =H2 -> 1.06 | J12: 0.03 | K12: 215 | L12: 29 | M12: 36 | N12: =K12-(L12+M12)/2 -> 182.5 | P12: =SQRT((K12+(L12+M12)/2)) -> 15.732133 | Q12: =N12/G12 -> 0.13444326 | R12: =Q12/H12/J12 -> 4.2277754 | S12: ± | T12: =P12/N12*R12 -> 0.3644489 | U12: =R12/60*1000 -> 70.462923 | V12: ± | W12: =T12/R12*U12 -> 6.0741483
A13: RGTh | B13: 228Ac | C13: 968 | D13: 14 | E13: 0.18 | G13: =G3 -> 1357.45 | H13: =H2 -> 1.06 | J13: 0.018 | K13: 130 | L13: 34 | M13: 34 | N13: =K13-(L13+M13)/2 -> 96 | P13: =SQRT((K13+(L13+M13)/2)) -> 12.806248 | Q13: =N13/G13 -> 0.070720837 | R13: =Q13/H13/J13 -> 3.7065428 | S13: ± | T13: =P13/N13*R13 -> 0.49444696 | U13: =R13/60*1000 -> 61.775714 | V13: ± | W13: =T13/R13*U13 -> 8.2407827
B14: Somme 226Ra | G14: =G2 -> 1357.45 | H14: =H2 -> 1.06 | I14: 0.005 | J14: =J4+J5+J6 -> 0.264 | K14: =K4+K5+K6 -> 4125 | L14: =L4+L5+L6 -> 181 | M14: =M4+M5+M6 -> 163 | N14: =N4+N5+N6 -> 3953 | O14: ± | P14: =SQRT((K14+(L14+M14)/2)) -> 65.551506 | Q14: =N14/G14 -> 2.9120778 | R14: =(Q14/H14/J14) -> 10.406224 | S14: ± | T14: =P14/N14*R14 -> 0.17256354 | U14: =R14/60*1000 -> 173.43707 | V14: ± | W14: =T14/R14*U14 -> 2.876059
B15: Somme 228Th | G15: =G14 -> 1357.45 | H15: =H14 -> 1.06 | I15: 0.005 | J15: =J9+J10 -> 0.215 | K15: =K9+K10 -> 1787 | L15: =L9+L10 -> 157 | M15: =M9+M10 -> 145 | N15: =N9+N10 -> 1636 | O15: ± | P15: =SQRT((K15+(L15+M15)/2)) -> 44.022721 | Q15: =N15/G15 -> 1.2052009 | R15: =(Q15/H15/J15) -> 5.2882884 | S15: ± | T15: =P15/N15*R15 -> 0.14230125 | U15: =R15/60*1000 -> 88.13814 | V15: ± | W15: =T15/R15*U15 -> 2.3716875 | X15: 3225
B16: Somme 228Ra | G16: =G10 -> 1357.45 | H16: =H10 -> 1.06 | I16: 0.005 | J16: =J11+J12+J13 -> 0.079 | K16: =K11+K12+K13 -> 612 | L16: =L11+L12+L13 -> 113 | M16: =M11+M12+M13 -> 123 | N16: =N11+N12+N13 -> 494 | O16: ± | P16: =SQRT((K16+(L16+M16)/2)) -> 27.018512 | Q16: =N16/G16 -> 0.36391764 | R16: =(Q16/H16/J16) -> 4.3458042 | S16: ± | T16: =P16/N16*R16 -> 0.23768656 | U16: =R16/60*1000 -> 72.430069 | V16: ± | W16: =T16/R16*U16 -> 3.9614427 | X16: 3225
A18: NOI_7 | B18: 81 447,000
A20: Isotope | B20: Energie(Kev) | C20: Somme pic | D20: Somme bkg gauche | E20: Somme bkg droit | F20: Somme-bkg | G20: Sigma
A21: 210Pb | B21: 46.4991 | C21: 2 202 | D21: 243 | E21: 208 | F21: 1 999 | G21: 46.93
A22: 241Am | B22: 59.5631 | C22: 261 | D22: 176 | E22: 185 | F22: 100 | G22: 16.16
A23: 214Pb | B23: 295.178 | C23: 1 335 | D23: 68 | E23: 64 | F23: 1 274 | G23: 36.54
A24: 214Pb | B24: 351.881 | C24: 2 099 | D24: 64 | E24: 58 | F24: 2 044 | G24: 45.81
A25: 214Bi | B25: 609.176 | C25: 691 | D25: 49 | E25: 41 | F25: 648 | G25: 26.29
A26: 137Cs | B26: 661.617 | C26: 3 246 | D26: 51 | E26: 34 | F26: 3 205 | G26: 56.97
A27: 40K | B27: 1460.19 | C27: 1 139 | D27: 30 | E27: 26 | F27: 1 112 | G27: 33.75
A28: 214Bi | B28: 1121.17 | C28: 132 | D28: 28 | E28: 22 | F28: 108 | G28: 11.49
A29: 228Ac | B29: 1775.39 | C29: 3 | D29: 15 | E29: 8 | F29: -8 | G29: 1.73
A30: 234Th | B30: 63.3618 | C30: 2 146 | D30: 222 | E30: 208 | F30: 1 952 | G30: 46.32
A31: 226Ra | B31: 185.848 | C31: 1 729 | D31: 120 | E31: 98 | F31: 1 633 | G31: 41.58
A32: 212Pb | B32: 238.567 | C32: 1 557 | D32: 117 | E32: 96 | F32: 1 457 | G32: 39.46
A33: 208Tl | B33: 582.956 | C33: 230 | D33: 40 | E33: 49 | F33: 188 | G33: 15.17
A34: 228Ac | B34: 338.076 | C34: 267 | D34: 50 | E34: 53 | F34: 220 | G34: 16.34
A35: 228Ac | B35: 910.852 | C35: 215 | D35: 29 | E35: 36 | F35: 184 | G35: 14.66
A36: 228Ac | B36: 968.852 | C36: 130 | D36: 34 | E36: 34 | F36: 97 | G36: 11.4
A37: 235U | B37: 143.691 | C37: 438 | D37: 115 | E37: 122 | F37: 299 | G37: 20.93

Sheet 8
A1: NOM | B1: Nucleide | C1: E kev | D1: Canaux | E1: %emis | F1: Rendement | G1: temps | H1: poids | I1: bdf | J1: eff | K1: pic1 | L1: bdfg | M1: bdfd | O1: pic net | Q1: cpm | S1: dpm/g | V1: Bq/k | X1: Data Certif
A2: RGU | B2: 210Pb | C2: 46.5 | D2: 9 | E2: 0.04 | F2: 0.535 | G2: =80594/60 -> 1343.2333 | H2: =2.97-1.77 -> 1.2 | I2: 0 | J2: 0.0214 | K2: 1649 | L2: 242 | M2: 220 | N2: =K2-(L2+M2)/2 -> 1418 | O2: ± | P2: =SQRT((K2+(L2+M2)/2)) -> 43.358967 | Q2: =N2/G2 -> 1.0556617 | R2: =(Q2/H2/J2) -> 41.108322 | S2: ± | T2: =P2/N2*R2 -> 1.2569918 | U2: =R2/60*1000 -> 685.1387 | V2: ± | W2: =T2/R2*U2 -> 20.949863 | X2: 4940
A3: IAEA447 | B3: 241Am | C3: 59.5 | D3: 8 | E3: 0.363 | F3: 0.71625344 | G3: =G2 -> 1343.2333 | H3: =H2 -> 1.2 | I3: 0 | J3: 0.26 | K3: 229 | L3: 203 | M3: 210 | N3: =K3-(L3+M3)/2 -> 22.5 | O3: ± | P3: =SQRT((K3+(L3+M3)/2)) -> 20.868637 | Q3: =N3/G3 -> 0.016750627 | R3: =Q3/H3/J3 -> 0.053687906 | S3: ± | T3: =P3/N3*R3 -> 0.049795262 | U3: =R3/60*1000 -> 0.89479843 | V3: ± | W3: =T3/R3*U3 -> 0.82992104 | X3: 2.15
A4: RGU1 | B4: 214Bi | C4: 295 | D4: 11 | E4: 0.192 | F4: 0.421875 | G4: =G2 -> 1343.2333 | H4: =H2 -> 1.2 | J4: 0.081 | K4: 1561 | L4: 73 | M4: 62 | N4: =K4-(L4+M4)/2 -> 1493.5 | O4: ± | P4: =SQRT((K4+(L4+M4)/2)) -> 40.354678 | Q4: =N4/G4 -> 1.1118694 | R4: =(Q4/H4/J4) -> 11.438985 | S4: ± | T4: =P4/N4*R4 -> 0.30908374 | U4: =R4/60*1000 -> 190.64975 | V4: ± | W4: =T4/R4*U4 -> 5.1513956 | X4: 4940
A5: RGU1 | B5: 214Bi | C5: 352 | D5: 12 | E5: 0.371 | F5: 0.36927224 | G5: =G2 -> 1343.2333 | H5: =H2 -> 1.2 | I5: 0.002 | J5: 0.137 | K5: 2566 | L5: 85 | M5: 55 | N5: =K5-(L5+M5)/2 -> 2496 | O5: ± | P5: =SQRT((K5+(L5+M5)/2)) -> 51.341991 | Q5: =N5/G5 -> 1.8582028 | R5: =(Q5/H5/J5) -> 11.302937 | S5: ± | T5: =P5/N5*R5 -> 0.23249811 | U5: =R5/60*1000 -> 188.38228 | V5: ± | W5: =T5/R5*U5 -> 3.8749685 | X5: 4940
A6: RGU1 | B6: 214Bi | C6: 609 | D6: 16 | E6: 0.461 | F6: 0.09978308 | G6: =G2 -> 1343.2333 | H6: =H2 -> 1.2 | I6: 0.002 | J6: 0.046 | K6: 896 | L6: 59 | M6: 48 | N6: =K6-(L6+M6)/2 -> 842.5 | O6: ± | P6: =SQRT((K6+(L6+M6)/2)) -> 30.813958 | Q6: =N6/G6 -> 0.62721791 | R6: =(Q6/H6/J6) -> 11.362643 | S6: ± | T6: =P6/N6*R6 -> 0.41558221 | U6: =R6/60*1000 -> 189.37739 | V6: ± | W6: =T6/R6*U6 -> 6.9263701 | X6: 4940
A7: IAEA447 | B7: 137Cs | C7: 661 | D7: 20 | E7: 0.8462 | F7: 0.29189317 | G7: =G2 -> 1343.2333 | H7: =H2 -> 1.2 | I7: 0.001 | J7: 0.247 | K7: 1975 | L7: 54 | M7: 48 | N7: =K7-(L7+M7)/2 -> 1924 | O7: ± | P7: =SQRT((K7+(L7+M7)/2)) -> 45.01111 | Q7: =N7/G7 -> 1.4323647 | R7: =Q7/H7/J7 -> 4.8325394 | S7: ± | T7: =P7/N7*R7 -> 0.11305507 | U7: =R7/60*1000 -> 80.542324 | V7: ± | W7: =T7/R7*U7 -> 1.8842512 | X7: 335
A8: RGU | B8: 40K | C8: 1460 | D8: 20 | E8: 0.107 | F8: 0.14485981 | G8: =G2 -> 1343.2333 | H8: =H2 -> 1.2 | I8: 0.004 | J8: 0.0155 | K8: 1175 | L8: 25 | M8: 28 | N8: =K8-(L8+M8)/2 -> 1148.5 | O8: ± | P8: =SQRT((K8+(L8+M8)/2)) -> 34.66266 | Q8: =N8/G8 -> 0.85502643 | R8: =Q8/H8/J8 -> 45.969163 | S8: ± | T8: =P8/N8*R8 -> 1.3873866 | U8: =R8/60*1000 -> 766.15271 | V8: ± | W8: =T8/R8*U8 -> 23.123109 | X8: 550
A9: RGTh | B9: 212Pb | C9: 238 | D9: 11 | E9: 0.431 | G9: =G3 -> 1343.2333 | H9: =H2 -> 1.2 | J9: 0.19 | K9: 1598 | L9: 102 | M9: 108 | N9: =K9-(L9+M9)/2 -> 1493 | P9: =SQRT((K9+(L9+M9)/2)) -> 41.267421 | Q9: =N9/G9 -> 1.1114971 | R9: =Q9/H9/J9 -> 4.8749874 | S9: ± | T9: =P9/N9*R9 -> 0.13474759 | U9: =R9/60*1000 -> 81.24979 | V9: ± | W9: =T9/R9*U9 -> 2.2457932
A10: RGTh | B10: 208Tl | C10: 583 | D10: 13 | G10: =G4 -> 1343.2333 | H10: =H2 -> 1.2 | J10: 0.025 | K10: 219 | L10: 41 | M10: 49 | N10: =K10-(L10+M10)/2 -> 174 | P10: =SQRT((K10+(L10+M10)/2)) -> 16.248077 | Q10: =N10/G10 -> 0.12953818 | R10: =Q10/H10/J10 -> 4.3179393 | S10: ± | T10: =P10/N10*R10 -> 0.4032081 | U10: =R10/60*1000 -> 71.965655 | V10: ± | W10: =T10/R10*U10 -> 6.720135
